Workbook
Name Data_Base: #REF!

Sheet DB
A1: ADEP | B1: SID 12R | C1: SID 30L | D1: Sector | E1: ACC_Adyacente
A2: MMMX | B2: UDGUV | C2: {=_xlfn.SWITCH(Tabla42[[#This Row],[SID 12R]],"UDGUV","UDGUV","OMSUK","ROTGI","ENEBA","NOSUG","NUDAL","NUDAL","TAKUX","CZM","HECAT","CZM","CZM","CZM","")} -> UDGUV | D2: {=_xlfn.IFS(OR(Tabla42[[#This Row],[SID 12R]]="UDGUV",Tabla42[[#This Row],[SID 30L]]="UDGUV"),"Sector 2",OR(Tabla42[[#This Row],[SID 12R]]="OMSUK",Tabla42[[#This Row],[SID 30L]]="OMSUK",Tabla42[[#This Row],[SID 12R]]="ROTGI",Tabla42[[#This Row],[SID 30L]]="ROTGI",Tabla42[[#This Row],[SID 12R]]="ENEBA",Tabla42[[#This Row],[SID 30L]]="ENEBA",Tabla42[[#This Row],[SID 12R]]="NUDAL",Tabla42[[#This Row],[SID 30L]]="NUDAL"),"Sector 3",OR(Tabla42[[#This Row],[SID 12R]]="TAKUX",Tabla42[[#This Row],[SID 30L]]="TAKUX",Tabla42[[#This Row],[SID 12R]]="TAKUK",Tabla42[[#This Row],[SID 30L]]="TAKUK",Tabla42[[#This Row],[SID 12R]]="HECAT",Tabla42[[#This Row],[SID 30L]]="HECAT",Tabla42[[#This Row],[SID 12R]]="CZM",Tabla42[[#This Row],[SID 30L]]="CZM"),"Sector 7",TRUE,"")} -> Sector 2 | E2: MMEX
A3: CYYZ | B3: OMSUK | C3: {=_xlfn.SWITCH(Tabla42[[#This Row],[SID 12R]],"UDGUV","UDGUV","OMSUK","ROTGI","ENEBA","NOSUG","NUDAL","NUDAL","TAKUX","CZM","HECAT","CZM","CZM","CZM","")} -> ROTGI | D3: {=_xlfn.IFS(OR(Tabla42[[#This Row],[SID 12R]]="UDGUV",Tabla42[[#This Row],[SID 30L]]="UDGUV"),"Sector 2",OR(Tabla42[[#This Row],[SID 12R]]="OMSUK",Tabla42[[#This Row],[SID 30L]]="OMSUK",Tabla42[[#This Row],[SID 12R]]="ROTGI",Tabla42[[#This Row],[SID 30L]]="ROTGI",Tabla42[[#This Row],[SID 12R]]="ENEBA",Tabla42[[#This Row],[SID 30L]]="ENEBA",Tabla42[[#This Row],[SID 12R]]="NUDAL",Tabla42[[#This Row],[SID 30L]]="NUDAL"),"Sector 3",OR(Tabla42[[#This Row],[SID 12R]]="TAKUX",Tabla42[[#This Row],[SID 30L]]="TAKUX",Tabla42[[#This Row],[SID 12R]]="TAKUK",Tabla42[[#This Row],[SID 30L]]="TAKUK",Tabla42[[#This Row],[SID 12R]]="HECAT",Tabla42[[#This Row],[SID 30L]]="HECAT",Tabla42[[#This Row],[SID 12R]]="CZM",Tabla42[[#This Row],[SID 30L]]="CZM"),"Sector 7",TRUE,"")} -> Sector 3 | E3: KZHU
A4: MMMY | B4: UDGUV | C4: {=_xlfn.SWITCH(Tabla42[[#This Row],[SID 12R]],"UDGUV","UDGUV","OMSUK","ROTGI","ENEBA","NOSUG","NUDAL","NUDAL","TAKUX","CZM","HECAT","CZM","CZM","CZM","")} -> UDGUV | D4: {=_xlfn.IFS(OR(Tabla42[[#This Row],[SID 12R]]="UDGUV",Tabla42[[#This Row],[SID 30L]]="UDGUV"),"Sector 2",OR(Tabla42[[#This Row],[SID 12R]]="OMSUK",Tabla42[[#This Row],[SID 30L]]="OMSUK",Tabla42[[#This Row],[SID 12R]]="ROTGI",Tabla42[[#This Row],[SID 30L]]="ROTGI",Tabla42[[#This Row],[SID 12R]]="ENEBA",Tabla42[[#This Row],[SID 30L]]="ENEBA",Tabla42[[#This Row],[SID 12R]]="NUDAL",Tabla42[[#This Row],[SID 30L]]="NUDAL"),"Sector 3",OR(Tabla42[[#This Row],[SID 12R]]="TAKUX",Tabla42[[#This Row],[SID 30L]]="TAKUX",Tabla42[[#This Row],[SID 12R]]="TAKUK",Tabla42[[#This Row],[SID 30L]]="TAKUK",Tabla42[[#This Row],[SID 12R]]="HECAT",Tabla42[[#This Row],[SID 30L]]="HECAT",Tabla42[[#This Row],[SID 12R]]="CZM",Tabla42[[#This Row],[SID 30L]]="CZM"),"Sector 7",TRUE,"")} -> Sector 2 | E4: MMTY
A5: MMTO | B5: UDGUV | C5: {=_xlfn.SWITCH(Tabla42[[#This Row],[SID 12R]],"UDGUV","UDGUV","OMSUK","ROTGI","ENEBA","NOSUG","NUDAL","NUDAL","TAKUX","CZM","HECAT","CZM","CZM","CZM","")} -> UDGUV | D5: {=_xlfn.IFS(OR(Tabla42[[#This Row],[SID 12R]]="UDGUV",Tabla42[[#This Row],[SID 30L]]="UDGUV"),"Sector 2",OR(Tabla42[[#This Row],[SID 12R]]="OMSUK",Tabla42[[#This Row],[SID 30L]]="OMSUK",Tabla42[[#This Row],[SID 12R]]="ROTGI",Tabla42[[#This Row],[SID 30L]]="ROTGI",Tabla42[[#This Row],[SID 12R]]="ENEBA",Tabla42[[#This Row],[SID 30L]]="ENEBA",Tabla42[[#This Row],[SID 12R]]="NUDAL",Tabla42[[#This Row],[SID 30L]]="NUDAL"),"Sector 3",OR(Tabla42[[#This Row],[SID 12R]]="TAKUX",Tabla42[[#This Row],[SID 30L]]="TAKUX",Tabla42[[#This Row],[SID 12R]]="TAKUK",Tabla42[[#This Row],[SID 30L]]="TAKUK",Tabla42[[#This Row],[SID 12R]]="HECAT",Tabla42[[#This Row],[SID 30L]]="HECAT",Tabla42[[#This Row],[SID 12R]]="CZM",Tabla42[[#This Row],[SID 30L]]="CZM"),"Sector 7",TRUE,"")} -> Sector 2 | E5: MMEX
A6: KDFW | B6: ENEBA | C6: {=_xlfn.SWITCH(Tabla42[[#This Row],[SID 12R]],"UDGUV","UDGUV","OMSUK","ROTGI","ENEBA","NOSUG","NUDAL","NUDAL","TAKUX","CZM","HECAT","CZM","CZM","CZM","")} -> NOSUG | D6: {=_xlfn.IFS(OR(Tabla42[[#This Row],[SID 12R]]="UDGUV",Tabla42[[#This Row],[SID 30L]]="UDGUV"),"Sector 2",OR(Tabla42[[#This Row],[SID 12R]]="OMSUK",Tabla42[[#This Row],[SID 30L]]="OMSUK",Tabla42[[#This Row],[SID 12R]]="ROTGI",Tabla42[[#This Row],[SID 30L]]="ROTGI",Tabla42[[#This Row],[SID 12R]]="ENEBA",Tabla42[[#This Row],[SID 30L]]="ENEBA",Tabla42[[#This Row],[SID 12R]]="NUDAL",Tabla42[[#This Row],[SID 30L]]="NUDAL"),"Sector 3",OR(Tabla42[[#This Row],[SID 12R]]="TAKUX",Tabla42[[#This Row],[SID 30L]]="TAKUX",Tabla42[[#This Row],[SID 12R]]="TAKUK",Tabla42[[#This Row],[SID 30L]]="TAKUK",Tabla42[[#This Row],[SID 12R]]="HECAT",Tabla42[[#This Row],[SID 30L]]="HECAT",Tabla42[[#This Row],[SID 12R]]="CZM",Tabla42[[#This Row],[SID 30L]]="CZM"),"Sector 7",TRUE,"")} -> Sector 3 | E6: KZHU
A7: KORD | B7: ENEBA | C7: {=_xlfn.SWITCH(Tabla42[[#This Row],[SID 12R]],"UDGUV","UDGUV","OMSUK","ROTGI","ENEBA","NOSUG","NUDAL","NUDAL","TAKUX","CZM","HECAT","CZM","CZM","CZM","")} -> NOSUG | D7: {=_xlfn.IFS(OR(Tabla42[[#This Row],[SID 12R]]="UDGUV",Tabla42[[#This Row],[SID 30L]]="UDGUV"),"Sector 2",OR(Tabla42[[#This Row],[SID 12R]]="OMSUK",Tabla42[[#This Row],[SID 30L]]="OMSUK",Tabla42[[#This Row],[SID 12R]]="ROTGI",Tabla42[[#This Row],[SID 30L]]="ROTGI",Tabla42[[#This Row],[SID 12R]]="ENEBA",Tabla42[[#This Row],[SID 30L]]="ENEBA",Tabla42[[#This Row],[SID 12R]]="NUDAL",Tabla42[[#This Row],[SID 30L]]="NUDAL"),"Sector 3",OR(Tabla42[[#This Row],[SID 12R]]="TAKUX",Tabla42[[#This Row],[SID 30L]]="TAKUX",Tabla42[[#This Row],[SID 12R]]="TAKUK",Tabla42[[#This Row],[SID 30L]]="TAKUK",Tabla42[[#This Row],[SID 12R]]="HECAT",Tabla42[[#This Row],[SID 30L]]="HECAT",Tabla42[[#This Row],[SID 12R]]="CZM",Tabla42[[#This Row],[SID 30L]]="CZM"),"Sector 7",TRUE,"")} -> Sector 3 | E7: KZHU
A8: KATL | B8: ENEBA | C8: {=_xlfn.SWITCH(Tabla42[[#This Row],[SID 12R]],"UDGUV","UDGUV","OMSUK","ROTGI","ENEBA","NOSUG","NUDAL","NUDAL","TAKUX","CZM","HECAT","CZM","CZM","CZM","")} -> NOSUG | D8: {=_xlfn.IFS(OR(Tabla42[[#This Row],[SID 12R]]="UDGUV",Tabla42[[#This Row],[SID 30L]]="UDGUV"),"Sector 2",OR(Tabla42[[#This Row],[SID 12R]]="OMSUK",Tabla42[[#This Row],[SID 30L]]="OMSUK",Tabla42[[#This Row],[SID 12R]]="ROTGI",Tabla42[[#This Row],[SID 30L]]="ROTGI",Tabla42[[#This Row],[SID 12R]]="ENEBA",Tabla42[[#This Row],[SID 30L]]="ENEBA",Tabla42[[#This Row],[SID 12R]]="NUDAL",Tabla42[[#This Row],[SID 30L]]="NUDAL"),"Sector 3",OR(Tabla42[[#This Row],[SID 12R]]="TAKUX",Tabla42[[#This Row],[SID 30L]]="TAKUX",Tabla42[[#This Row],[SID 12R]]="TAKUK",Tabla42[[#This Row],[SID 30L]]="TAKUK",Tabla42[[#This Row],[SID 12R]]="HECAT",Tabla42[[#This Row],[SID 30L]]="HECAT",Tabla42[[#This Row],[SID 12R]]="CZM",Tabla42[[#This Row],[SID 30L]]="CZM"),"Sector 7",TRUE,"")} -> Sector 3 | E8: KZHU
A9: KLAX | B9: UDGUV | C9: {=_xlfn.SWITCH(Tabla42[[#This Row],[SID 12R]],"UDGUV","UDGUV","OMSUK","ROTGI","ENEBA","NOSUG","NUDAL","NUDAL","TAKUX","CZM","HECAT","CZM","CZM","CZM","")} -> UDGUV | D9: {=_xlfn.IFS(OR(Tabla42[[#This Row],[SID 12R]]="UDGUV",Tabla42[[#This Row],[SID 30L]]="UDGUV"),"Sector 2",OR(Tabla42[[#This Row],[SID 12R]]="OMSUK",Tabla42[[#This Row],[SID 30L]]="OMSUK",Tabla42[[#This Row],[SID 12R]]="ROTGI",Tabla42[[#This Row],[SID 30L]]="ROTGI",Tabla42[[#This Row],[SID 12R]]="ENEBA",Tabla42[[#This Row],[SID 30L]]="ENEBA",Tabla42[[#This Row],[SID 12R]]="NUDAL",Tabla42[[#This Row],[SID 30L]]="NUDAL"),"Sector 3",OR(Tabla42[[#This Row],[SID 12R]]="TAKUX",Tabla42[[#This Row],[SID 30L]]="TAKUX",Tabla42[[#This Row],[SID 12R]]="TAKUK",Tabla42[[#This Row],[SID 30L]]="TAKUK",Tabla42[[#This Row],[SID 12R]]="HECAT",Tabla42[[#This Row],[SID 30L]]="HECAT",Tabla42[[#This Row],[SID 12R]]="CZM",Tabla42[[#This Row],[SID 30L]]="CZM"),"Sector 7",TRUE,"")} -> Sector 2 | E9: MMTY
A10: MMSM | B10: UDGUV | C10: {=_xlfn.SWITCH(Tabla42[[#This Row],[SID 12R]],"UDGUV","UDGUV","OMSUK","ROTGI","ENEBA","NOSUG","NUDAL","NUDAL","TAKUX","CZM","HECAT","CZM","CZM","CZM","")} -> UDGUV | D10: {=_xlfn.IFS(OR(Tabla42[[#This Row],[SID 12R]]="UDGUV",Tabla42[[#This Row],[SID 30L]]="UDGUV"),"Sector 2",OR(Tabla42[[#This Row],[SID 12R]]="OMSUK",Tabla42[[#This Row],[SID 30L]]="OMSUK",Tabla42[[#This Row],[SID 12R]]="ROTGI",Tabla42[[#This Row],[SID 30L]]="ROTGI",Tabla42[[#This Row],[SID 12R]]="ENEBA",Tabla42[[#This Row],[SID 30L]]="ENEBA",Tabla42[[#This Row],[SID 12R]]="NUDAL",Tabla42[[#This Row],[SID 30L]]="NUDAL"),"Sector 3",OR(Tabla42[[#This Row],[SID 12R]]="TAKUX",Tabla42[[#This Row],[SID 30L]]="TAKUX",Tabla42[[#This Row],[SID 12R]]="TAKUK",Tabla42[[#This Row],[SID 30L]]="TAKUK",Tabla42[[#This Row],[SID 12R]]="HECAT",Tabla42[[#This Row],[SID 30L]]="HECAT",Tabla42[[#This Row],[SID 12R]]="CZM",Tabla42[[#This Row],[SID 30L]]="CZM"),"Sector 7",TRUE,"")} -> Sector 2 | E10: MMEX
A11: KIAH | B11: ENEBA | C11: {=_xlfn.SWITCH(Tabla42[[#This Row],[SID 12R]],"UDGUV","UDGUV","OMSUK","ROTGI","ENEBA","NOSUG","NUDAL","NUDAL","TAKUX","CZM","HECAT","CZM","CZM","CZM","")} -> NOSUG | D11: {=_xlfn.IFS(OR(Tabla42[[#This Row],[SID 12R]]="UDGUV",Tabla42[[#This Row],[SID 30L]]="UDGUV"),"Sector 2",OR(Tabla42[[#This Row],[SID 12R]]="OMSUK",Tabla42[[#This Row],[SID 30L]]="OMSUK",Tabla42[[#This Row],[SID 12R]]="ROTGI",Tabla42[[#This Row],[SID 30L]]="ROTGI",Tabla42[[#This Row],[SID 12R]]="ENEBA",Tabla42[[#This Row],[SID 30L]]="ENEBA",Tabla42[[#This Row],[SID 12R]]="NUDAL",Tabla42[[#This Row],[SID 30L]]="NUDAL"),"Sector 3",OR(Tabla42[[#This Row],[SID 12R]]="TAKUX",Tabla42[[#This Row],[SID 30L]]="TAKUX",Tabla42[[#This Row],[SID 12R]]="TAKUK",Tabla42[[#This Row],[SID 30L]]="TAKUK",Tabla42[[#This Row],[SID 12R]]="HECAT",Tabla42[[#This Row],[SID 30L]]="HECAT",Tabla42[[#This Row],[SID 12R]]="CZM",Tabla42[[#This Row],[SID 30L]]="CZM"),"Sector 7",TRUE,"")} -> Sector 3 | E11: KZHU
A12: CYUL | B12: OMSUK | C12: {=_xlfn.SWITCH(Tabla42[[#This Row],[SID 12R]],"UDGUV","UDGUV","OMSUK","ROTGI","ENEBA","NOSUG","NUDAL","NUDAL","TAKUX","CZM","HECAT","CZM","CZM","CZM","")} -> ROTGI | D12: {=_xlfn.IFS(OR(Tabla42[[#This Row],[SID 12R]]="UDGUV",Tabla42[[#This Row],[SID 30L]]="UDGUV"),"Sector 2",OR(Tabla42[[#This Row],[SID 12R]]="OMSUK",Tabla42[[#This Row],[SID 30L]]="OMSUK",Tabla42[[#This Row],[SID 12R]]="ROTGI",Tabla42[[#This Row],[SID 30L]]="ROTGI",Tabla42[[#This Row],[SID 12R]]="ENEBA",Tabla42[[#This Row],[SID 30L]]="ENEBA",Tabla42[[#This Row],[SID 12R]]="NUDAL",Tabla42[[#This Row],[SID 30L]]="NUDAL"),"Sector 3",OR(Tabla42[[#This Row],[SID 12R]]="TAKUX",Tabla42[[#This Row],[SID 30L]]="TAKUX",Tabla42[[#This Row],[SID 12R]]="TAKUK",Tabla42[[#This Row],[SID 30L]]="TAKUK",Tabla42[[#This Row],[SID 12R]]="HECAT",Tabla42[[#This Row],[SID 30L]]="HECAT",Tabla42[[#This Row],[SID 12R]]="CZM",Tabla42[[#This Row],[SID 30L]]="CZM"),"Sector 7",TRUE,"")} -> Sector 3 | E12: KZHU
A13: MMGL | B13: UDGUV | C13: {=_xlfn.SWITCH(Tabla42[[#This Row],[SID 12R]],"UDGUV","UDGUV","OMSUK","ROTGI","ENEBA","NOSUG","NUDAL","NUDAL","TAKUX","CZM","HECAT","CZM","CZM","CZM","")} -> UDGUV | D13: {=_xlfn.IFS(OR(Tabla42[[#This Row],[SID 12R]]="UDGUV",Tabla42[[#This Row],[SID 30L]]="UDGUV"),"Sector 2",OR(Tabla42[[#This Row],[SID 12R]]="OMSUK",Tabla42[[#This Row],[SID 30L]]="OMSUK",Tabla42[[#This Row],[SID 12R]]="ROTGI",Tabla42[[#This Row],[SID 30L]]="ROTGI",Tabla42[[#This Row],[SID 12R]]="ENEBA",Tabla42[[#This Row],[SID 30L]]="ENEBA",Tabla42[[#This Row],[SID 12R]]="NUDAL",Tabla42[[#This Row],[SID 30L]]="NUDAL"),"Sector 3",OR(Tabla42[[#This Row],[SID 12R]]="TAKUX",Tabla42[[#This Row],[SID 30L]]="TAKUX",Tabla42[[#This Row],[SID 12R]]="TAKUK",Tabla42[[#This Row],[SID 30L]]="TAKUK",Tabla42[[#This Row],[SID 12R]]="HECAT",Tabla42[[#This Row],[SID 30L]]="HECAT",Tabla42[[#This Row],[SID 12R]]="CZM",Tabla42[[#This Row],[SID 30L]]="CZM"),"Sector 7",TRUE,"")} -> Sector 2 | E13: MMEX
... A212: SVMC | B212: TAKUX | C212: {=_xlfn.SWITCH(Tabla42[[#This Row],[SID 12R]],"UDGUV","UDGUV","OMSUK","ROTGI","ENEBA","NOSUG","NUDAL","NUDAL","TAKUX","CZM","HECAT","CZM","CZM","CZM","")} -> CZM | D212: {=_xlfn.IFS(OR(Tabla42[[#This Row],[SID 12R]]="UDGUV",Tabla42[[#This Row],[SID 30L]]="UDGUV"),"Sector 2",OR(Tabla42[[#This Row],[SID 12R]]="OMSUK",Tabla42[[#This Row],[SID 30L]]="OMSUK",Tabla42[[#This Row],[SID 12R]]="ROTGI",Tabla42[[#This Row],[SID 30L]]="ROTGI",Tabla42[[#This Row],[SID 12R]]="ENEBA",Tabla42[[#This Row],[SID 30L]]="ENEBA",Tabla42[[#This Row],[SID 12R]]="NUDAL",Tabla42[[#This Row],[SID 30L]]="NUDAL"),"Sector 3",OR(Tabla42[[#This Row],[SID 12R]]="TAKUX",Tabla42[[#This Row],[SID 30L]]="TAKUX",Tabla42[[#This Row],[SID 12R]]="TAKUK",Tabla42[[#This Row],[SID 30L]]="TAKUK",Tabla42[[#This Row],[SID 12R]]="HECAT",Tabla42[[#This Row],[SID 30L]]="HECAT",Tabla42[[#This Row],[SID 12R]]="CZM",Tabla42[[#This Row],[SID 30L]]="CZM"),"Sector 7",TRUE,"")} -> Sector 7 | E212: MHCC
A213: KPTK | B213: OMSUK | C213: ROTGI | D213: {=_xlfn.IFS(OR(Tabla42[[#This Row],[SID 12R]]="UDGUV",Tabla42[[#This Row],[SID 30L]]="UDGUV"),"Sector 2",OR(Tabla42[[#This Row],[SID 12R]]="OMSUK",Tabla42[[#This Row],[SID 30L]]="OMSUK",Tabla42[[#This Row],[SID 12R]]="ROTGI",Tabla42[[#This Row],[SID 30L]]="ROTGI",Tabla42[[#This Row],[SID 12R]]="ENEBA",Tabla42[[#This Row],[SID 30L]]="ENEBA",Tabla42[[#This Row],[SID 12R]]="NUDAL",Tabla42[[#This Row],[SID 30L]]="NUDAL"),"Sector 3",OR(Tabla42[[#This Row],[SID 12R]]="TAKUX",Tabla42[[#This Row],[SID 30L]]="TAKUX",Tabla42[[#This Row],[SID 12R]]="TAKUK",Tabla42[[#This Row],[SID 30L]]="TAKUK",Tabla42[[#This Row],[SID 12R]]="HECAT",Tabla42[[#This Row],[SID 30L]]="HECAT",Tabla42[[#This Row],[SID 12R]]="CZM",Tabla42[[#This Row],[SID 30L]]="CZM"),"Sector 7",TRUE,"")} -> Sector 3 | E213: KZHU
A214: TJIG | B214: NUDAL | C214: {=_xlfn.SWITCH(Tabla42[[#This Row],[SID 12R]],"UDGUV","UDGUV","OMSUK","ROTGI","ENEBA","NOSUG","NUDAL","NUDAL","TAKUX","CZM","HECAT","CZM","CZM","CZM","")} -> NUDAL | D214: {=_xlfn.IFS(OR(Tabla42[[#This Row],[SID 12R]]="UDGUV",Tabla42[[#This Row],[SID 30L]]="UDGUV"),"Sector 2",OR(Tabla42[[#This Row],[SID 12R]]="OMSUK",Tabla42[[#This Row],[SID 30L]]="OMSUK",Tabla42[[#This Row],[SID 12R]]="ROTGI",Tabla42[[#This Row],[SID 30L]]="ROTGI",Tabla42[[#This Row],[SID 12R]]="ENEBA",Tabla42[[#This Row],[SID 30L]]="ENEBA",Tabla42[[#This Row],[SID 12R]]="NUDAL",Tabla42[[#This Row],[SID 30L]]="NUDAL"),"Sector 3",OR(Tabla42[[#This Row],[SID 12R]]="TAKUX",Tabla42[[#This Row],[SID 30L]]="TAKUX",Tabla42[[#This Row],[SID 12R]]="TAKUK",Tabla42[[#This Row],[SID 30L]]="TAKUK",Tabla42[[#This Row],[SID 12R]]="HECAT",Tabla42[[#This Row],[SID 30L]]="HECAT",Tabla42[[#This Row],[SID 12R]]="CZM",Tabla42[[#This Row],[SID 30L]]="CZM"),"Sector 7",TRUE,"")} -> Sector 3 | E214: MUFH
A215: MMPN | B215: UDGUV | C215: {=_xlfn.SWITCH(Tabla42[[#This Row],[SID 12R]],"UDGUV","UDGUV","OMSUK","ROTGI","ENEBA","NOSUG","NUDAL","NUDAL","TAKUX","CZM","HECAT","CZM","CZM","CZM","")} -> UDGUV | D215: {=_xlfn.IFS(OR(Tabla42[[#This Row],[SID 12R]]="UDGUV",Tabla42[[#This Row],[SID 30L]]="UDGUV"),"Sector 2",OR(Tabla42[[#This Row],[SID 12R]]="OMSUK",Tabla42[[#This Row],[SID 30L]]="OMSUK",Tabla42[[#This Row],[SID 12R]]="ROTGI",Tabla42[[#This Row],[SID 30L]]="ROTGI",Tabla42[[#This Row],[SID 12R]]="ENEBA",Tabla42[[#This Row],[SID 30L]]="ENEBA",Tabla42[[#This Row],[SID 12R]]="NUDAL",Tabla42[[#This Row],[SID 30L]]="NUDAL"),"Sector 3",OR(Tabla42[[#This Row],[SID 12R]]="TAKUX",Tabla42[[#This Row],[SID 30L]]="TAKUX",Tabla42[[#This Row],[SID 12R]]="TAKUK",Tabla42[[#This Row],[SID 30L]]="TAKUK",Tabla42[[#This Row],[SID 12R]]="HECAT",Tabla42[[#This Row],[SID 30L]]="HECAT",Tabla42[[#This Row],[SID 12R]]="CZM",Tabla42[[#This Row],[SID 30L]]="CZM"),"Sector 7",TRUE,"")} -> Sector 2 | E215: MMEX
A216: KSAN | B216: UDGUV | C216: {=_xlfn.SWITCH(Tabla42[[#This Row],[SID 12R]],"UDGUV","UDGUV","OMSUK","ROTGI","ENEBA","NOSUG","NUDAL","NUDAL","TAKUX","CZM","HECAT","CZM","CZM","CZM","")} -> UDGUV | D216: {=_xlfn.IFS(OR(Tabla42[[#This Row],[SID 12R]]="UDGUV",Tabla42[[#This Row],[SID 30L]]="UDGUV"),"Sector 2",OR(Tabla42[[#This Row],[SID 12R]]="OMSUK",Tabla42[[#This Row],[SID 30L]]="OMSUK",Tabla42[[#This Row],[SID 12R]]="ROTGI",Tabla42[[#This Row],[SID 30L]]="ROTGI",Tabla42[[#This Row],[SID 12R]]="ENEBA",Tabla42[[#This Row],[SID 30L]]="ENEBA",Tabla42[[#This Row],[SID 12R]]="NUDAL",Tabla42[[#This Row],[SID 30L]]="NUDAL"),"Sector 3",OR(Tabla42[[#This Row],[SID 12R]]="TAKUX",Tabla42[[#This Row],[SID 30L]]="TAKUX",Tabla42[[#This Row],[SID 12R]]="TAKUK",Tabla42[[#This Row],[SID 30L]]="TAKUK",Tabla42[[#This Row],[SID 12R]]="HECAT",Tabla42[[#This Row],[SID 30L]]="HECAT",Tabla42[[#This Row],[SID 12R]]="CZM",Tabla42[[#This Row],[SID 30L]]="CZM"),"Sector 7",TRUE,"")} -> Sector 2 | E216: MMTY
A217: LFBP | B217: NUDAL | C217: {=_xlfn.SWITCH(Tabla42[[#This Row],[SID 12R]],"UDGUV","UDGUV","OMSUK","ROTGI","ENEBA","NOSUG","NUDAL","NUDAL","TAKUX","CZM","HECAT","CZM","CZM","CZM","")} -> NUDAL | D217: {=_xlfn.IFS(OR(Tabla42[[#This Row],[SID 12R]]="UDGUV",Tabla42[[#This Row],[SID 30L]]="UDGUV"),"Sector 2",OR(Tabla42[[#This Row],[SID 12R]]="OMSUK",Tabla42[[#This Row],[SID 30L]]="OMSUK",Tabla42[[#This Row],[SID 12R]]="ROTGI",Tabla42[[#This Row],[SID 30L]]="ROTGI",Tabla42[[#This Row],[SID 12R]]="ENEBA",Tabla42[[#This Row],[SID 30L]]="ENEBA",Tabla42[[#This Row],[SID 12R]]="NUDAL",Tabla42[[#This Row],[SID 30L]]="NUDAL"),"Sector 3",OR(Tabla42[[#This Row],[SID 12R]]="TAKUX",Tabla42[[#This Row],[SID 30L]]="TAKUX",Tabla42[[#This Row],[SID 12R]]="TAKUK",Tabla42[[#This Row],[SID 30L]]="TAKUK",Tabla42[[#This Row],[SID 12R]]="HECAT",Tabla42[[#This Row],[SID 30L]]="HECAT",Tabla42[[#This Row],[SID 12R]]="CZM",Tabla42[[#This Row],[SID 30L]]="CZM"),"Sector 7",TRUE,"")} -> Sector 3 | E217: MUFH
A218: KPIE | B218: ENEBA | C218: {=_xlfn.SWITCH(Tabla42[[#This Row],[SID 12R]],"UDGUV","UDGUV","OMSUK","ROTGI","ENEBA","NOSUG","NUDAL","NUDAL","TAKUX","CZM","HECAT","CZM","CZM","CZM","")} -> NOSUG | D218: {=_xlfn.IFS(OR(Tabla42[[#This Row],[SID 12R]]="UDGUV",Tabla42[[#This Row],[SID 30L]]="UDGUV"),"Sector 2",OR(Tabla42[[#This Row],[SID 12R]]="OMSUK",Tabla42[[#This Row],[SID 30L]]="OMSUK",Tabla42[[#This Row],[SID 12R]]="ROTGI",Tabla42[[#This Row],[SID 30L]]="ROTGI",Tabla42[[#This Row],[SID 12R]]="ENEBA",Tabla42[[#This Row],[SID 30L]]="ENEBA",Tabla42[[#This Row],[SID 12R]]="NUDAL",Tabla42[[#This Row],[SID 30L]]="NUDAL"),"Sector 3",OR(Tabla42[[#This Row],[SID 12R]]="TAKUX",Tabla42[[#This Row],[SID 30L]]="TAKUX",Tabla42[[#This Row],[SID 12R]]="TAKUK",Tabla42[[#This Row],[SID 30L]]="TAKUK",Tabla42[[#This Row],[SID 12R]]="HECAT",Tabla42[[#This Row],[SID 30L]]="HECAT",Tabla42[[#This Row],[SID 12R]]="CZM",Tabla42[[#This Row],[SID 30L]]="CZM"),"Sector 7",TRUE,"")} -> Sector 3 | E218: KZHU
A219: KDAL | B219: ENEBA | C219: {=_xlfn.SWITCH(Tabla42[[#This Row],[SID 12R]],"UDGUV","UDGUV","OMSUK","ROTGI","ENEBA","NOSUG","NUDAL","NUDAL","TAKUX","CZM","HECAT","CZM","CZM","CZM","")} -> NOSUG | D219: {=_xlfn.IFS(OR(Tabla42[[#This Row],[SID 12R]]="UDGUV",Tabla42[[#This Row],[SID 30L]]="UDGUV"),"Sector 2",OR(Tabla42[[#This Row],[SID 12R]]="OMSUK",Tabla42[[#This Row],[SID 30L]]="OMSUK",Tabla42[[#This Row],[SID 12R]]="ROTGI",Tabla42[[#This Row],[SID 30L]]="ROTGI",Tabla42[[#This Row],[SID 12R]]="ENEBA",Tabla42[[#This Row],[SID 30L]]="ENEBA",Tabla42[[#This Row],[SID 12R]]="NUDAL",Tabla42[[#This Row],[SID 30L]]="NUDAL"),"Sector 3",OR(Tabla42[[#This Row],[SID 12R]]="TAKUX",Tabla42[[#This Row],[SID 30L]]="TAKUX",Tabla42[[#This Row],[SID 12R]]="TAKUK",Tabla42[[#This Row],[SID 30L]]="TAKUK",Tabla42[[#This Row],[SID 12R]]="HECAT",Tabla42[[#This Row],[SID 30L]]="HECAT",Tabla42[[#This Row],[SID 12R]]="CZM",Tabla42[[#This Row],[SID 30L]]="CZM"),"Sector 7",TRUE,"")} -> Sector 3 | E219: KZHU
A220: MMJC | B220: UDGUV | C220: {=_xlfn.SWITCH(Tabla42[[#This Row],[SID 12R]],"UDGUV","UDGUV","OMSUK","ROTGI","ENEBA","NOSUG","NUDAL","NUDAL","TAKUX","CZM","HECAT","CZM","CZM","CZM","")} -> UDGUV | D220: {=_xlfn.IFS(OR(Tabla42[[#This Row],[SID 12R]]="UDGUV",Tabla42[[#This Row],[SID 30L]]="UDGUV"),"Sector 2",OR(Tabla42[[#This Row],[SID 12R]]="OMSUK",Tabla42[[#This Row],[SID 30L]]="OMSUK",Tabla42[[#This Row],[SID 12R]]="ROTGI",Tabla42[[#This Row],[SID 30L]]="ROTGI",Tabla42[[#This Row],[SID 12R]]="ENEBA",Tabla42[[#This Row],[SID 30L]]="ENEBA",Tabla42[[#This Row],[SID 12R]]="NUDAL",Tabla42[[#This Row],[SID 30L]]="NUDAL"),"Sector 3",OR(Tabla42[[#This Row],[SID 12R]]="TAKUX",Tabla42[[#This Row],[SID 30L]]="TAKUX",Tabla42[[#This Row],[SID 12R]]="TAKUK",Tabla42[[#This Row],[SID 30L]]="TAKUK",Tabla42[[#This Row],[SID 12R]]="HECAT",Tabla42[[#This Row],[SID 30L]]="HECAT",Tabla42[[#This Row],[SID 12R]]="CZM",Tabla42[[#This Row],[SID 30L]]="CZM"),"Sector 7",TRUE,"")} -> Sector 2 | E220: MMEX
A221: MHTG | B221: CZM | C221: {=_xlfn.SWITCH(Tabla42[[#This Row],[SID 12R]],"UDGUV","UDGUV","OMSUK","ROTGI","ENEBA","NOSUG","NUDAL","NUDAL","TAKUX","CZM","HECAT","CZM","CZM","CZM","")} -> CZM | D221: {=_xlfn.IFS(OR(Tabla42[[#This Row],[SID 12R]]="UDGUV",Tabla42[[#This Row],[SID 30L]]="UDGUV"),"Sector 2",OR(Tabla42[[#This Row],[SID 12R]]="OMSUK",Tabla42[[#This Row],[SID 30L]]="OMSUK",Tabla42[[#This Row],[SID 12R]]="ROTGI",Tabla42[[#This Row],[SID 30L]]="ROTGI",Tabla42[[#This Row],[SID 12R]]="ENEBA",Tabla42[[#This Row],[SID 30L]]="ENEBA",Tabla42[[#This Row],[SID 12R]]="NUDAL",Tabla42[[#This Row],[SID 30L]]="NUDAL"),"Sector 3",OR(Tabla42[[#This Row],[SID 12R]]="TAKUX",Tabla42[[#This Row],[SID 30L]]="TAKUX",Tabla42[[#This Row],[SID 12R]]="TAKUK",Tabla42[[#This Row],[SID 30L]]="TAKUK",Tabla42[[#This Row],[SID 12R]]="HECAT",Tabla42[[#This Row],[SID 30L]]="HECAT",Tabla42[[#This Row],[SID 12R]]="CZM",Tabla42[[#This Row],[SID 30L]]="CZM"),"Sector 7",TRUE,"")} -> Sector 7 | E221: MHCC
C222: {=_xlfn.SWITCH(Tabla42[[#This Row],[SID 12R]],"UDGUV","UDGUV","OMSUK","ROTGI","ENEBA","NOSUG","NUDAL","NUDAL","TAKUX","CZM","HECAT","CZM","CZM","CZM","")} | D222: {=_xlfn.IFS(OR(Tabla42[[#This Row],[SID 12R]]="UDGUV",Tabla42[[#This Row],[SID 30L]]="UDGUV"),"Sector 2",OR(Tabla42[[#This Row],[SID 12R]]="OMSUK",Tabla42[[#This Row],[SID 30L]]="OMSUK",Tabla42[[#This Row],[SID 12R]]="ROTGI",Tabla42[[#This Row],[SID 30L]]="ROTGI",Tabla42[[#This Row],[SID 12R]]="ENEBA",Tabla42[[#This Row],[SID 30L]]="ENEBA",Tabla42[[#This Row],[SID 12R]]="NUDAL",Tabla42[[#This Row],[SID 30L]]="NUDAL"),"Sector 3",OR(Tabla42[[#This Row],[SID 12R]]="TAKUX",Tabla42[[#This Row],[SID 30L]]="TAKUX",Tabla42[[#This Row],[SID 12R]]="TAKUK",Tabla42[[#This Row],[SID 30L]]="TAKUK",Tabla42[[#This Row],[SID 12R]]="HECAT",Tabla42[[#This Row],[SID 30L]]="HECAT",Tabla42[[#This Row],[SID 12R]]="CZM",Tabla42[[#This Row],[SID 30L]]="CZM"),"Sector 7",TRUE,"")}

Sheet 2026-09-01
A1: callsign | B1: adep | C1: ades | D1: aircraft_type | E1: aircraft_registration | F1: atd | G1: dep_runway | H1: route | I1: rfl | J1: flight_rule | K1: flight_type | L1: distance_flown_in_fir | M1: exit_point | N1: exit_hour | O1: exit_level | P1: wtc | Q1: nfl | R1: SID_resuelto | S1: Hora_UTC | T1: Sector_resuelto
A2: VOI1051 | B2: MMUN | C2: MMGL | D2: A21N | E2: XAVUK | F2: 46266.017 | G2: 12R | H2: UDGUV2A UDGUV 2050N08810W 2056N08826W NUBIT DCT RIBET UT101 ENAGA DCT OVAGO UT123 IGSON IGSON1B | I2: 340 | J2: I | K2: S | L2: 862 | M2: NUBIT | N2: 46266.064 | O2: 340 | P2: M | Q2: 190 | R2: =IF(G2="12R",_xlfn.XLOOKUP(C2,DB!$A$2:$A$222,DB!$B$2:$B$222,""),IF(G2="30L",_xlfn.XLOOKUP(C2,DB!$A$2:$A$222,DB!$C$2:$C$222,""),"")) -> UDGUV | S2: =HOUR(F2) -> 0 | T2: =_xlfn.XLOOKUP(C2,DB!$A$2:$A$222,DB!$D$2:$D$222,"") -> Sector 2
A3: WJA2777 | B3: MMUN | C3: CYYZ | D3: B38M | E3: CGAMQ | F3: 46266.02 | G3: 12R | H3: S12R SR00 SR01 ROTGI UM219 MYDIA/M078F350 M219 KNOST/N0459F350 DCT CAMJO DCT DANCO DCT OXMAN LINNG3 | I3: 350 | J3: I | K3: S | L3: 359 | M3: MYDIA | N3: 46266.04 | O3: 350 | P3: M | Q3: 40 | R3: =IF(G3="12R",_xlfn.XLOOKUP(C3,DB!$A$2:$A$222,DB!$B$2:$B$222,""),IF(G3="30L",_xlfn.XLOOKUP(C3,DB!$A$2:$A$222,DB!$C$2:$C$222,""),"")) -> OMSUK | S3: =HOUR(F3) -> 0 | T3: =_xlfn.XLOOKUP(C3,DB!$A$2:$A$222,DB!$D$2:$D$222,"") -> Sector 3
A4: VOI5589 | B4: MMUN | C4: MMMY | D4: A320 | E4: XAVVC | F4: 46266.033 | G4: 12R | H4: UDGUV2A UDGUV UT78 DURPI DCT NOTEN UT37 SESNO UJ15E RETOS RETOS1A | I4: 340 | J4: I | K4: S | L4: 878 | M4: NOTEN | N4: 46266.08 | O4: 340 | P4: M | Q4: 190 | R4: =IF(G4="12R",_xlfn.XLOOKUP(C4,DB!$A$2:$A$222,DB!$B$2:$B$222,""),IF(G4="30L",_xlfn.XLOOKUP(C4,DB!$A$2:$A$222,DB!$C$2:$C$222,""),"")) -> UDGUV | S4: =HOUR(F4) -> 0 | T4: =_xlfn.XLOOKUP(C4,DB!$A$2:$A$222,DB!$D$2:$D$222,"") -> Sector 2
A5: WFL2502 | B5: MMUN | C5: LEMD | D5: A359 | E5: ECNOI | F5: 46266.034 | G5: 12R | H5: NUDAL1A NUDAL UV106 PODON UG765 MAXIM Y262 CANVI/N0496F370 Y262 ZFP DCT VENDS DCT HOOKY DCT SNAGY/M085F370 M203 SELIM/M085F370 DCT 40N060W 43N050W/M085F390 46N040W 46N030W 46N020W/M085F390 DCT HIDRA/N0488F390 DCT STG/N0486F240 N733 ZMR | I5: 350 | J5: I | K5: S | L5: 136 | M5: NUDAL | N5: 46266.044 | O5: 210 | P5: H | Q5: 190 | R5: =IF(G5="12R",_xlfn.XLOOKUP(C5,DB!$A$2:$A$222,DB!$B$2:$B$222,""),IF(G5="30L",_xlfn.XLOOKUP(C5,DB!$A$2:$A$222,DB!$C$2:$C$222,""),"")) -> NUDAL | S5: =HOUR(F5) -> 0 | T5: =_xlfn.XLOOKUP(C5,DB!$A$2:$A$222,DB!$D$2:$D$222,"") -> Sector 3
A6: AMX555 | B6: MMUN | C6: MMMX | D6: B39M | E6: XAMIJ | F6: 46266.037 | G6: 12R | H6: UDGUV2A UDGUV UT78 MEDOS UT20 UBVOV/N0457F340 UT101 UMAVO/N0456F300 UT101 ENAGA ENAGA3A | I6: 360 | J6: I | K6: S | L6: 859 | M6: UBVOV | N6: 46266.082 | O6: 360 | P6: M | Q6: 190 | R6: =IF(G6="12R",_xlfn.XLOOKUP(C6,DB!$A$2:$A$222,DB!$B$2:$B$222,""),IF(G6="30L",_xlfn.XLOOKUP(C6,DB!$A$2:$A$222,DB!$C$2:$C$222,""),"")) -> UDGUV | S6: =HOUR(F6) -> 0 | T6: =_xlfn.XLOOKUP(C6,DB!$A$2:$A$222,DB!$D$2:$D$222,"") -> Sector 2
A7: BAW2202 | B7: MMUN | C7: EGKK | D7: B772 | E7: GYMMB | F7: 46266.045 | G7: 12R | H7: S12R T12R6 UN415 NUDAL UV106 PODON UG765 MAXIM DCT EYW DCT PBI/M083F350 DCT SNAGY/M083F370 M203 SELIM DCT 43N050W/M083F390 46N040W 48N030W 48N020W 48N015W DCT OMOKO DCT GUNSO DCT GAPLI/N0473F390 DCT SIDDI/N0458F350 DCT DAWLY/N0418F270 DCT ELRIP DCT OTMET OTMET1G | I7: 350 | J7: I | K7: S | L7: 136 | M7: NUDAL | N7: 46266.055 | O7: 207 | P7: H | Q7: 190 | R7: =IF(G7="12R",_xlfn.XLOOKUP(C7,DB!$A$2:$A$222,DB!$B$2:$B$222,""),IF(G7="30L",_xlfn.XLOOKUP(C7,DB!$A$2:$A$222,DB!$C$2:$C$222,""),"")) -> NUDAL | S7: =HOUR(F7) -> 1 | T7: =_xlfn.XLOOKUP(C7,DB!$A$2:$A$222,DB!$D$2:$D$222,"") -> Sector 3
A8: XASSE | B8: MMUN | C8: MMTO | D8: E135 | F8: 46266.054 | G8: 12R | H8: UDGUV2A UDGUV UBVOV UT20 PAZ UT104 LENUL DCT | I8: 380 | J8: I | K8: G | L8: 859 | M8: UBVOV | N8: 46266.1 | O8: 380 | P8: M | Q8: 30 | R8: =IF(G8="12R",_xlfn.XLOOKUP(C8,DB!$A$2:$A$222,DB!$B$2:$B$222,""),IF(G8="30L",_xlfn.XLOOKUP(C8,DB!$A$2:$A$222,DB!$C$2:$C$222,""),"")) -> UDGUV | S8: =HOUR(F8) -> 1 | T8: =_xlfn.XLOOKUP(C8,DB!$A$2:$A$222,DB!$D$2:$D$222,"") -> Sector 2
A9: VOC4071 | B9: MMUN | C9: MROC | D9: A20N | E9: N547VL | F9: 46266.07 | G9: 12R | H9: S12R T12R6 ALSUP UB881 BTO UM206 VIVIT DCT PIRAS BARRA4P | I9: 370 | J9: I | K9: S | L9: 219 | M9: ANIKO | N9: 46266.083 | O9: 330 | P9: M | Q9: 190 | R9: =IF(G9="12R",_xlfn.XLOOKUP(C9,DB!$A$2:$A$222,DB!$B$2:$B$222,""),IF(G9="30L",_xlfn.XLOOKUP(C9,DB!$A$2:$A$222,DB!$C$2:$C$222,""),"")) -> CZM | S9: =HOUR(F9) -> 1 | T9: =_xlfn.XLOOKUP(C9,DB!$A$2:$A$222,DB!$D$2:$D$222,"") -> Sector 7
A10: VIV1373 | B10: MMUN | C10: MMMX | D10: A21N | E10: XAVXD | F10: 46266.071 | G10: 12R | H10: UDGUV2A UDGUV UT78 MEDOS UT20 UBVOV UT101 ENAGA ENAGA3A | I10: 340 | J10: I | K10: S | L10: 859 | M10: UBVOV | N10: 46266.118 | O10: 340 | P10: M | Q10: 190 | R10: =IF(G10="12R",_xlfn.XLOOKUP(C10,DB!$A$2:$A$222,DB!$B$2:$B$222,""),IF(G10="30L",_xlfn.XLOOKUP(C10,DB!$A$2:$A$222,DB!$C$2:$C$222,""),"")) -> UDGUV | S10: =HOUR(F10) -> 1 | T10: =_xlfn.XLOOKUP(C10,DB!$A$2:$A$222,DB!$D$2:$D$222,"") -> Sector 2
A11: ROU1813 | B11: MMUN | C11: CYYZ | D11: A321 | E11: CFYXF | F11: 46266.079 | G11: 12R | H11: S12R SR00 SR01 OMSUK UM219 MYDIA M219 NAVVL/M078F330 M219 CULLY/N0463F330 M219 KNOST DCT CAMJO/N0462F350 Q99 BLAAN Q69 RICCS DCT OXMAN LINNG3 | I11: 310 | J11: I | K11: S | L11: 359 | M11: MYDIA | N11: 46266.099 | O11: 310 | P11: M | Q11: 40 | R11: =IF(G11="12R",_xlfn.XLOOKUP(C11,DB!$A$2:$A$222,DB!$B$2:$B$222,""),IF(G11="30L",_xlfn.XLOOKUP(C11,DB!$A$2:$A$222,DB!$C$2:$C$222,""),"")) -> OMSUK | S11: =HOUR(F11) -> 1 | T11: =_xlfn.XLOOKUP(C11,DB!$A$2:$A$222,DB!$D$2:$D$222,"") -> Sector 3
A12: VTM9901 | B12: MMUN | C12: MMQT | D12: B734 | E12: XATIF | F12: 46266.081 | G12: 12R | H12: S12R 2100N08650W T12R7 2052N08722W 2053N08753W 2052N08801W 2052N08812W 2054N08819W 2054N08827W 2113N09006W 2115N09025W 2135N09324W 2136N09331W TARBI UJ17 QET | I12: 360 | J12: I | K12: S | L12: 865 | M12: 2137N09459W | N12: 46266.127 | O12: 360 | P12: M | Q12: 40 | R12: =IF(G12="12R",_xlfn.XLOOKUP(C12,DB!$A$2:$A$222,DB!$B$2:$B$222,""),IF(G12="30L",_xlfn.XLOOKUP(C12,DB!$A$2:$A$222,DB!$C$2:$C$222,""),"")) -> UDGUV | S12: =HOUR(F12) -> 1 | T12: =_xlfn.XLOOKUP(C12,DB!$A$2:$A$222,DB!$D$2:$D$222,"") -> Sector 2
A13: ESF610 | B13: MMUN | C13: MMMD | D13: B734 | E13: XASLG | F13: 46266.092 | G13: 12R | H13: S12R T12R6 2058N08652W 2047N08747W NAPRI NAPRI1A | I13: 220 | J13: I | K13: S | L13: 354 | M13: MMMD | N13: 46266.117 | O13: 0 | P13: M | Q13: 190 | R13: =IF(G13="12R",_xlfn.XLOOKUP(C13,DB!$A$2:$A$222,DB!$B$2:$B$222,""),IF(G13="30L",_xlfn.XLOOKUP(C13,DB!$A$2:$A$222,DB!$C$2:$C$222,""),"")) -> UDGUV | S13: =HOUR(F13) -> 2 | T13: =_xlfn.XLOOKUP(C13,DB!$A$2:$A$222,DB!$D$2:$D$222,"") -> Sector 2
A14: EVE814 | B14: MMUN | C14: LEMD | D14: A333 | E14: ECODR | F14: 46266.115 | G14: 12R | H14: S12R T12R6 UN415 UN413 MAXIM Y262 GOPEY/N0478F370 Y262 ZFP BR65V STIFF A699 SUMRS/M082F370 M204 SOORY DCT 43N050W/M082F370 46N040W/M082F390 47N030W 47N020W 46N015W/N0465F390 DCT PITAX DCT STG DCT DESAT DCT ZMR | I14: 350 | J14: I | K14: S | L14: 137 | M14: 2135N08548W | N14: 46266.125 | O14: 205 | P14: H | Q14: 190 | R14: =IF(G14="12R",_xlfn.XLOOKUP(C14,DB!$A$2:$A$222,DB!$B$2:$B$222,""),IF(G14="30L",_xlfn.XLOOKUP(C14,DB!$A$2:$A$222,DB!$C$2:$C$222,""),"")) -> NUDAL | S14: =HOUR(F14) -> 2 | T14: =_xlfn.XLOOKUP(C14,DB!$A$2:$A$222,DB!$D$2:$D$222,"") -> Sector 3
A15: VIV1017 | B15: MMUN | C15: MMMX | D15: A20N | E15: XAVMF | F15: 46266.133 | G15: 12R | H15: UDGUV2A UDGUV UT78 MEDOS DCT UBVOV DCT UMAVO UT101 ENAGA ENAGA3A | I15: 380 | J15: I | K15: S | L15: 859 | M15: UBVOV | N15: 46266.181 | O15: 380 | P15: M | Q15: 190 | R15: =IF(G15="12R",_xlfn.XLOOKUP(C15,DB!$A$2:$A$222,DB!$B$2:$B$222,""),IF(G15="30L",_xlfn.XLOOKUP(C15,DB!$A$2:$A$222,DB!$C$2:$C$222,""),"")) -> UDGUV | S15: =HOUR(F15) -> 3 | T15: =_xlfn.XLOOKUP(C15,DB!$A$2:$A$222,DB!$D$2:$D$222,"") -> Sector 2
A16: VTM2202 | B16: MMUN | C16: MMVA | D16: B734 | E16: XAVHS | F16: 46266.137 | G16: 12R | H16: S12R T12R6 UN418 2052N08721W 2052N08722W 2051N08727W AGAVE UJ9 VSA | I16: 320 | J16: I | K16: S | L16: 721 | M16: MMVA | N16: 46266.181 | O16: 0 | P16: M | Q16: 190 | R16: =IF(G16="12R",_xlfn.XLOOKUP(C16,DB!$A$2:$A$222,DB!$B$2:$B$222,""),IF(G16="30L",_xlfn.XLOOKUP(C16,DB!$A$2:$A$222,DB!$C$2:$C$222,""),"")) -> UDGUV | S16: =HOUR(F16) -> 3 | T16: =_xlfn.XLOOKUP(C16,DB!$A$2:$A$222,DB!$D$2:$D$222,"") -> Sector 2
A17: VIV2140 | B17: MMUN | C17: MMGL | D17: A21N | E17: XAVXU | F17: 46266.139 | G17: 12R | H17: S12R T12R6 UN418 2058N08806W 2058N08807W 2148N09501W SLP UT147 AGU UT44 MEZCA MEZCA1A | I17: 360 | J17: I | K17: S | L17: 861 | M17: 2148N09459W | N17: 46266.185 | O17: 360 | P17: M | Q17: 190 | R17: =IF(G17="12R",_xlfn.XLOOKUP(C17,DB!$A$2:$A$222,DB!$B$2:$B$222,""),IF(G17="30L",_xlfn.XLOOKUP(C17,DB!$A$2:$A$222,DB!$C$2:$C$222,""),"")) -> UDGUV | S17: =HOUR(F17) -> 3 | T17: =_xlfn.XLOOKUP(C17,DB!$A$2:$A$222,DB!$D$2:$D$222,"") -> Sector 2
A18: VOI105 | B18: MMUN | C18: MMMX | D18: A321 | E18: XAVLT | F18: 46266.14 | G18: 12R | H18: S12R T12R6 UN418 2058N08656W UDGUV UT78 DURPI DCT UBVOV UT101 ENAGA ENAGA3A | I18: 360 | J18: I | K18: S | L18: 861 | M18: UBVOV | N18: 46266.187 | O18: 360 | P18: M | Q18: 190 | R18: =IF(G18="12R",_xlfn.XLOOKUP(C18,DB!$A$2:$A$222,DB!$B$2:$B$222,""),IF(G18="30L",_xlfn.XLOOKUP(C18,DB!$A$2:$A$222,DB!$C$2:$C$222,""),"")) -> UDGUV | S18: =HOUR(F18) -> 3 | T18: =_xlfn.XLOOKUP(C18,DB!$A$2:$A$222,DB!$D$2:$D$222,"") -> Sector 2
A19: VOI5593 | B19: MMUN | C19: MMMY | D19: A20N | E19: XATVM | F19: 46266.142 | G19: 12R | H19: S12R T12R6 UN418 UN409 2052N08738W 2101N08826W NOTEN UT37 SESNO UJ15E RETOS RETOS1A | I19: 380 | J19: I | K19: S | L19: 863 | M19: NOTEN | N19: 46266.187 | O19: 380 | P19: M | Q19: 190 | R19: =IF(G19="12R",_xlfn.XLOOKUP(C19,DB!$A$2:$A$222,DB!$B$2:$B$222,""),IF(G19="30L",_xlfn.XLOOKUP(C19,DB!$A$2:$A$222,DB!$C$2:$C$222,""),"")) -> UDGUV | S19: =HOUR(F19) -> 3 | T19: =_xlfn.XLOOKUP(C19,DB!$A$2:$A$222,DB!$D$2:$D$222,"") -> Sector 2
A20: VIV2022 | B20: MMUN | C20: MMTO | D20: A320 | E20: XAVAM | F20: 46266.149 | G20: 12R | H20: UDGUV2A UDGUV UT78 UKOKO 2045N08924W 2038N09040W AVIVI ELVED UT104 LENUL LENUL3A | I20: 360 | J20: I | K20: S | L20: 863 | M20: AVIVI | N20: 46266.196 | O20: 360 | P20: M | Q20: 190 | R20: =IF(G20="12R",_xlfn.XLOOKUP(C20,DB!$A$2:$A$222,DB!$B$2:$B$222,""),IF(G20="30L",_xlfn.XLOOKUP(C20,DB!$A$2:$A$222,DB!$C$2:$C$222,""),"")) -> UDGUV | S20: =HOUR(F20) -> 3 | T20: =_xlfn.XLOOKUP(C20,DB!$A$2:$A$222,DB!$D$2:$D$222,"") -> Sector 2
... A37: AAL316 | B37: MMUN | C37: KDFW | D37: B738 | E37: N970AN | F37: 46266.549 | G37: 12R | H37: S12R 2100N08650W NC011 2132N08652W 2205N08658W KEHLI A770 LEV DCT LSU DCT AEX DCT PNUTS BEREE3 | I37: 360 | J37: I | K37: S | L37: 531 | M37: KEHLI | N37: 46266.577 | O37: 360 | P37: M | Q37: 40 | R37: =IF(G37="12R",_xlfn.XLOOKUP(C37,DB!$A$2:$A$222,DB!$B$2:$B$222,""),IF(G37="30L",_xlfn.XLOOKUP(C37,DB!$A$2:$A$222,DB!$C$2:$C$222,""),"")) -> ENEBA | S37: =HOUR(F37) -> 13 | T37: =_xlfn.XLOOKUP(C37,DB!$A$2:$A$222,DB!$D$2:$D$222,"") -> Sector 3
A38: N68AR | B38: MMUN | C38: MMTO | D38: H25B | F38: 46266.55 | G38: 12R | H38: S12R 2101N08651W 2058N08651W CZA UT20 PAZ UT104 LENUL DCT | I38: 340 | J38: I | K38: G | L38: 859 | M38: UBVOV | N38: 46266.6 | O38: 340 | P38: M | Q38: 30 | R38: =IF(G38="12R",_xlfn.XLOOKUP(C38,DB!$A$2:$A$222,DB!$B$2:$B$222,""),IF(G38="30L",_xlfn.XLOOKUP(C38,DB!$A$2:$A$222,DB!$C$2:$C$222,""),"")) -> UDGUV | S38: =HOUR(F38) -> 13 | T38: =_xlfn.XLOOKUP(C38,DB!$A$2:$A$222,DB!$D$2:$D$222,"") -> Sector 2
A39: DAL609 | B39: MMUN | C39: KATL | D39: B738 | E39: N3743H | F39: 46266.552 | G39: 12R | H39: S12R SR00 SR01 ROTGI UM219 MYDIA M219 CIGAR M215 KNOST DCT CAMJO DCT LAIRI DCT LARZZ JJEDI4 | I39: 370 | J39: I | K39: S | L39: 359 | M39: MYDIA | N39: 46266.572 | O39: 370 | P39: M | Q39: 40 | R39: =IF(G39="12R",_xlfn.XLOOKUP(C39,DB!$A$2:$A$222,DB!$B$2:$B$222,""),IF(G39="30L",_xlfn.XLOOKUP(C39,DB!$A$2:$A$222,DB!$C$2:$C$222,""),"")) -> ENEBA | S39: =HOUR(F39) -> 13 | T39: =_xlfn.XLOOKUP(C39,DB!$A$2:$A$222,DB!$D$2:$D$222,"") -> Sector 3
A40: UAL1988 | B40: MMUN | C40: KEWR | D40: B39M | E40: N77581 | F40: 46266.583 | G40: 12R | H40: S12R 2101N08650W ROTGI UM219 ALPUK/N0464F330 UM219 MYDIA/N0464F350 M219 CIGAR M215 KNOST Q109 CAMJO Q99 QUART PHLBO4 | I40: 310 | J40: I | K40: S | L40: 345 | M40: MYDIA | N40: 46266.603 | O40: 350 | P40: M | Q40: 40 | R40: =IF(G40="12R",_xlfn.XLOOKUP(C40,DB!$A$2:$A$222,DB!$B$2:$B$222,""),IF(G40="30L",_xlfn.XLOOKUP(C40,DB!$A$2:$A$222,DB!$C$2:$C$222,""),"")) -> OMSUK | S40: =HOUR(F40) -> 13 | T40: =_xlfn.XLOOKUP(C40,DB!$A$2:$A$222,DB!$D$2:$D$222,"") -> Sector 3
A41: XBPGY | B41: MMUN | C41: MMVA | D41: C501 | F41: 46266.587 | G41: 12R | H41: S12R T12R6 UN418 UN409 UN419 2051N08727W 1951N08934W 1930N09014W 1852N09126W CME NOPON UJ9 VSA | I41: 280 | J41: I | K41: G | L41: 724 | M41: MMVA | N41: 46266.646 | O41: 0 | P41: L | Q41: 30 | R41: =IF(G41="12R",_xlfn.XLOOKUP(C41,DB!$A$2:$A$222,DB!$B$2:$B$222,""),IF(G41="30L",_xlfn.XLOOKUP(C41,DB!$A$2:$A$222,DB!$C$2:$C$222,""),"")) -> UDGUV | S41: =HOUR(F41) -> 14 | T41: =_xlfn.XLOOKUP(C41,DB!$A$2:$A$222,DB!$D$2:$D$222,"") -> Sector 2
A42: XAVGF | B42: MMUN | C42: MMUN | D42: B429 | F42: 46266.602 | G42: 12R | H42: LCLUN CUN | I42: 15 | J42: V | K42: G | L42: 297 | M42: MMUN | N42: 46266.673 | O42: 0 | P42: L | Q42: 15 | R42: =IF(G42="12R",_xlfn.XLOOKUP(C42,DB!$A$2:$A$222,DB!$B$2:$B$222,""),IF(G42="30L",_xlfn.XLOOKUP(C42,DB!$A$2:$A$222,DB!$C$2:$C$222,""),"")) | S42: =HOUR(F42) -> 14 | T42: =_xlfn.XLOOKUP(C42,DB!$A$2:$A$222,DB!$D$2:$D$222,"")
A43: AMX515 | B43: MMUN | C43: MMMX | D43: B39M | E43: XAIMH | F43: 46266.605 | G43: 12R | H43: UDGUV2A UDGUV UT78 MEDOS UT20 UBVOV UT101 UMAVO/N0452F300 UT101 ENAGA ENAGA3A | I43: 360 | J43: I | K43: S | L43: 859 | M43: UBVOV | N43: 46266.651 | O43: 360 | P43: M | Q43: 190 | R43: =IF(G43="12R",_xlfn.XLOOKUP(C43,DB!$A$2:$A$222,DB!$B$2:$B$222,""),IF(G43="30L",_xlfn.XLOOKUP(C43,DB!$A$2:$A$222,DB!$C$2:$C$222,""),"")) -> UDGUV | S43: =HOUR(F43) -> 14 | T43: =_xlfn.XLOOKUP(C43,DB!$A$2:$A$222,DB!$D$2:$D$222,"") -> Sector 2
A44: N300FB | B44: MMUN | C44: MMTO | D44: EPIC | F44: 46266.616 | G44: 12R | H44: S12R T12R6 UN418 UN409 2053N08715W CZ551 2053N08735W UBVOV UT20 PAZ UT104 LENUL DCT | I44: 280 | J44: I | K44: G | L44: 858 | M44: UBVOV | N44: 46266.683 | O44: 280 | P44: L | Q44: 30 | R44: =IF(G44="12R",_xlfn.XLOOKUP(C44,DB!$A$2:$A$222,DB!$B$2:$B$222,""),IF(G44="30L",_xlfn.XLOOKUP(C44,DB!$A$2:$A$222,DB!$C$2:$C$222,""),"")) -> UDGUV | S44: =HOUR(F44) -> 14 | T44: =_xlfn.XLOOKUP(C44,DB!$A$2:$A$222,DB!$D$2:$D$222,"") -> Sector 2
A45: ROU1885 | B45: MMUN | C45: CYUL | D45: A319 | E45: CGBHY | F45: 46266.625 | G45: 12R | H45: S12R SR00 SR01 SR02 SR03 SR04 SR05 ROTGI UM219 MYDIA/M078F350 M219 CULLY/N0458F350 M219 KNOST/N0454F370 DCT CAMJO DCT TEEEM Q99 POLYY DCT OGRAE DCT AUDII DCT FAK DCT RBV DCT LLUND DCT CAM DCT JASDU DCT PBERG CARTR5 | I45: 350 | J45: I | K45: S | L45: 359 | M45: MYDIA | N45: 46266.645 | O45: 350 | P45: M | Q45: 40 | R45: =IF(G45="12R",_xlfn.XLOOKUP(C45,DB!$A$2:$A$222,DB!$B$2:$B$222,""),IF(G45="30L",_xlfn.XLOOKUP(C45,DB!$A$2:$A$222,DB!$C$2:$C$222,""),"")) -> OMSUK | S45: =HOUR(F45) -> 14 | T45: =_xlfn.XLOOKUP(C45,DB!$A$2:$A$222,DB!$D$2:$D$222,"") -> Sector 3
A46: VOI5585 | B46: MMUN | C46: MMMY | D46: A320 | E46: XAVVC | F46: 46266.627 | G46: 12R | H46: S12R 2101N08650W 2058N08650W 2055N08734W DURPI DCT NOTEN UT37 SESNO UJ15E RETOS RETOS1A | I46: 360 | J46: I | K46: S | L46: 878 | M46: NOTEN | N46: 46266.673 | O46: 360 | P46: M | Q46: 190 | R46: =IF(G46="12R",_xlfn.XLOOKUP(C46,DB!$A$2:$A$222,DB!$B$2:$B$222,""),IF(G46="30L",_xlfn.XLOOKUP(C46,DB!$A$2:$A$222,DB!$C$2:$C$222,""),"")) -> UDGUV | S46: =HOUR(F46) -> 15 | T46: =_xlfn.XLOOKUP(C46,DB!$A$2:$A$222,DB!$D$2:$D$222,"") -> Sector 2
A47: ESF615 | B47: MMUN | C47: KMIA | D47: B734 | E47: XASLG | F47: 46266.645 | G47: 12R | H47: NUDAL1A NUDAL UV106 PODON UG765 EMOVI UG765 MAXIM SNDBR3 | I47: 330 | J47: I | K47: S | L47: 136 | M47: NUDAL | N47: 46266.654 | O47: 269 | P47: M | Q47: 190 | R47: =IF(G47="12R",_xlfn.XLOOKUP(C47,DB!$A$2:$A$222,DB!$B$2:$B$222,""),IF(G47="30L",_xlfn.XLOOKUP(C47,DB!$A$2:$A$222,DB!$C$2:$C$222,""),"")) -> NUDAL | S47: =HOUR(F47) -> 15 | T47: =_xlfn.XLOOKUP(C47,DB!$A$2:$A$222,DB!$D$2:$D$222,"") -> Sector 3
A48: VIV7032 | B48: MMUN | C48: MMTO | D48: A320 | E48: XAVAQ | F48: 46266.648 | G48: 12R | H48: S12R T12R6 UN418 UN409 UN419 UN432 2050N09148W 2050N09154W RIBET UT101 UMAVO UT104 LENUL LENUL3A | I48: 380 | J48: I | K48: N | L48: 859 | M48: 2037N09459W | N48: 46266.693 | O48: 380 | P48: M | Q48: 190 | R48: =IF(G48="12R",_xlfn.XLOOKUP(C48,DB!$A$2:$A$222,DB!$B$2:$B$222,""),IF(G48="30L",_xlfn.XLOOKUP(C48,DB!$A$2:$A$222,DB!$C$2:$C$222,""),"")) -> UDGUV | S48: =HOUR(F48) -> 15 | T48: =_xlfn.XLOOKUP(C48,DB!$A$2:$A$222,DB!$D$2:$D$222,"") -> Sector 2
A49: VIV1029 | B49: MMUN | C49: MMMX | D49: A20N | E49: XAVMF | F49: 46266.65 | G49: 12R | H49: UDGUV2A UDGUV UT78 MEDOS DCT UBVOV DCT UMAVO UT101 ENAGA ENAGA3A | I49: 380 | J49: I | K49: S | L49: 859 | M49: UBVOV | N49: 46266.696 | O49: 380 | P49: M | Q49: 190 | R49: =IF(G49="12R",_xlfn.XLOOKUP(C49,DB!$A$2:$A$222,DB!$B$2:$B$222,""),IF(G49="30L",_xlfn.XLOOKUP(C49,DB!$A$2:$A$222,DB!$C$2:$C$222,""),"")) -> UDGUV | S49: =HOUR(F49) -> 15 | T49: =_xlfn.XLOOKUP(C49,DB!$A$2:$A$222,DB!$D$2:$D$222,"") -> Sector 2
A50: VIV2164 | B50: MMUN | C50: MMMY | D50: A321 | E50: XAVBU | F50: 46266.652 | G50: 12R | H50: S12R T12R6 UN418 UN409 UN419 2050N08732W 2050N08735W 2050N08738W 2050N08743W 2055N08912W 2056N08930W S101 NOTEN/N0453F380 UT37 SESNO UJ15E RETOS RETOS1A | I50: 360 | J50: I | K50: S | L50: 878 | M50: NOTEN | N50: 46266.697 | O50: 360 | P50: M | Q50: 190 | R50: =IF(G50="12R",_xlfn.XLOOKUP(C50,DB!$A$2:$A$222,DB!$B$2:$B$222,""),IF(G50="30L",_xlfn.XLOOKUP(C50,DB!$A$2:$A$222,DB!$C$2:$C$222,""),"")) -> UDGUV | S50: =HOUR(F50) -> 15 | T50: =_xlfn.XLOOKUP(C50,DB!$A$2:$A$222,DB!$D$2:$D$222,"") -> Sector 2
A51: VOI1049 | B51: MMUN | C51: MMGL | D51: A20N | E51: XAVUP | F51: 46266.653 | G51: 12R | H51: UDGUV2A UDGUV 2049N08805W NUBIT DCT RIBET UT101 ENAGA DCT OVAGO UT123 IKLOK/N0371F240 UT123 IGSON/N0335F200 IGSON1B | I51: 380 | J51: I | K51: S | L51: 860 | M51: NUBIT | N51: 46266.699 | O51: 380 | P51: M | Q51: 190 | R51: =IF(G51="12R",_xlfn.XLOOKUP(C51,DB!$A$2:$A$222,DB!$B$2:$B$222,""),IF(G51="30L",_xlfn.XLOOKUP(C51,DB!$A$2:$A$222,DB!$C$2:$C$222,""),"")) -> UDGUV | S51: =HOUR(F51) -> 15 | T51: =_xlfn.XLOOKUP(C51,DB!$A$2:$A$222,DB!$D$2:$D$222,"") -> Sector 2
A52: VIV2278 | B52: MMUN | C52: MMSM | D52: A320 | E52: XAVAN | F52: 46266.657 | G52: 12R | H52: S12R T12R6 UN418 UN409 UN419 2050N08732W UBVOV UT20 TAJIN DCT VITOS VITOS2A | I52: 360 | J52: I | K52: S | L52: 859 | M52: UBVOV | N52: 46266.702 | O52: 360 | P52: M | Q52: 190 | R52: =IF(G52="12R",_xlfn.XLOOKUP(C52,DB!$A$2:$A$222,DB!$B$2:$B$222,""),IF(G52="30L",_xlfn.XLOOKUP(C52,DB!$A$2:$A$222,DB!$C$2:$C$222,""),"")) -> UDGUV | S52: =HOUR(F52) -> 15 | T52: =_xlfn.XLOOKUP(C52,DB!$A$2:$A$222,DB!$D$2:$D$222,"") -> Sector 2
A53: VOI101 | B53: MMUN | C53: MMMX | D53: A21N | E53: XAVUT | F53: 46266.667 | G53: 12R | H53: S12R T12R6 UN418 UN409 2054N08728W 2055N08734W UBVOV UT101 ENAGA ENAGA3A | I53: 340 | J53: I | K53: S | L53: 858 | M53: UBVOV | N53: 46266.714 | O53: 340 | P53: M | Q53: 190 | R53: =IF(G53="12R",_xlfn.XLOOKUP(C53,DB!$A$2:$A$222,DB!$B$2:$B$222,""),IF(G53="30L",_xlfn.XLOOKUP(C53,DB!$A$2:$A$222,DB!$C$2:$C$222,""),"")) -> UDGUV | S53: =HOUR(F53) -> 16 | T53: =_xlfn.XLOOKUP(C53,DB!$A$2:$A$222,DB!$D$2:$D$222,"") -> Sector 2
A54: VIV2176 | B54: MMUN | C54: MMMY | D54: A20N | E54: CCDBN | F54: 46266.672 | G54: 12R | H54: S12R T12R6 UN418 2056N08856W IZAML NOTEN UT37 SESNO UJ15E RETOS RETOS1A | I54: 380 | J54: I | K54: S | L54: 870 | M54: NOTEN | N54: 46266.716 | O54: 380 | P54: M | Q54: 190 | R54: =IF(G54="12R",_xlfn.XLOOKUP(C54,DB!$A$2:$A$222,DB!$B$2:$B$222,""),IF(G54="30L",_xlfn.XLOOKUP(C54,DB!$A$2:$A$222,DB!$C$2:$C$222,""),"")) -> UDGUV | S54: =HOUR(F54) -> 16 | T54: =_xlfn.XLOOKUP(C54,DB!$A$2:$A$222,DB!$D$2:$D$222,"") -> Sector 2
A55: AMX591 | B55: MMUN | C55: MMSM | D55: B738 | E55: XAAMS | F55: 46266.675 | G55: 12R | H55: S12R 2101N08651W 2058N08651W 2056N08726W 2056N08733W UBVOV UT101 UMAVO UT169 VITOS VITOS2A | I55: 360 | J55: I | K55: S | L55: 855 | M55: UBVOV | N55: 46266.721 | O55: 360 | P55: M | Q55: 190 | R55: =IF(G55="12R",_xlfn.XLOOKUP(C55,DB!$A$2:$A$222,DB!$B$2:$B$222,""),IF(G55="30L",_xlfn.XLOOKUP(C55,DB!$A$2:$A$222,DB!$C$2:$C$222,""),"")) -> UDGUV | S55: =HOUR(F55) -> 16 | T55: =_xlfn.XLOOKUP(C55,DB!$A$2:$A$222,DB!$D$2:$D$222,"") -> Sector 2
A56: VIV8005 | B56: MMUN | C56: MMCS | D56: A320 | E56: XAVAP | F56: 46266.68 | G56: 12R | H56: S12R T12R6 UN418 UN409 UN419 UN432 2050N08736W 2054N08857W 2054N08901W NOTEN DCT LIBOX DCT MOV UT3 URKOM UJ54 CJS DCT | I56: 380 | J56: I | K56: S | L56: 872 | M56: NOTEN | N56: 46266.723 | O56: 380 | P56: M | Q56: 190 | R56: =IF(G56="12R",_xlfn.XLOOKUP(C56,DB!$A$2:$A$222,DB!$B$2:$B$222,""),IF(G56="30L",_xlfn.XLOOKUP(C56,DB!$A$2:$A$222,DB!$C$2:$C$222,""),"")) -> UDGUV | S56: =HOUR(F56) -> 16 | T56: =_xlfn.XLOOKUP(C56,DB!$A$2:$A$222,DB!$D$2:$D$222,"") -> Sector 2
...

Sheet 2026-09-02
A1: callsign | B1: adep | C1: ades | D1: aircraft_type | E1: aircraft_registration | F1: atd | G1: dep_runway | H1: route | I1: rfl | J1: flight_rule | K1: flight_type | L1: distance_flown_in_fir | M1: exit_point | N1: exit_hour | O1: exit_level | P1: wtc | Q1: nfl | R1: SID_resuelto | S1: Hora_UTC | T1: Sector_resuelto
A2: LPE2457 | B2: MMUN | C2: SPJC | D2: A320 | E2: CCBLM | F2: 46267.001 | G2: 12R | H2: S12R 2101N08650W CN011 2020N08652W 2017N08652W 2014N08652W 2013N08652W 2007N08651W LIB UZ512 LIXAS UL203 ARNEL UM542 TAL UV1 ATATU ATATU4 | I2: 370 | J2: I | K2: S | L2: 201 | M2: 1916N08644W | N2: 46267.013 | O2: 293 | P2: M | Q2: 190 | R2: =IF(G2="12R",_xlfn.XLOOKUP(C2,DB!$A$2:$A$222,DB!$B$2:$B$222,""),IF(G2="30L",_xlfn.XLOOKUP(C2,DB!$A$2:$A$222,DB!$C$2:$C$222,""),"")) -> CZM | S2: =HOUR(F2) -> 0 | T2: =_xlfn.XLOOKUP(C2,DB!$A$2:$A$222,DB!$D$2:$D$222,"") -> Sector 7
A3: FLE2613 | B3: MMUN | C3: CYYZ | D3: B38M | E3: CFFLZ | F3: 46267.009 | G3: 12R | H3: S12R SR00 SR01 SR02 SR03 SR04 SR05 SR06 SR07 SR08 SR09 SR10 SR11 SR12 SR17 SR18 2113N08646W 2116N08647W OMSUK UM219 MYDIA M219 KNOST Q109 CAMJO DCT RIELE DCT BLAAN Q69 RICCS DCT OXMAN LINNG3 | I3: 370 | J3: I | K3: S | L3: 367 | M3: MYDIA | N3: 46267.03 | O3: 370 | P3: M | Q3: 40 | R3: =IF(G3="12R",_xlfn.XLOOKUP(C3,DB!$A$2:$A$222,DB!$B$2:$B$222,""),IF(G3="30L",_xlfn.XLOOKUP(C3,DB!$A$2:$A$222,DB!$C$2:$C$222,""),"")) -> OMSUK | S3: =HOUR(F3) -> 0 | T3: =_xlfn.XLOOKUP(C3,DB!$A$2:$A$222,DB!$D$2:$D$222,"") -> Sector 3
A4: VOI1051 | B4: MMUN | C4: MMGL | D4: A21N | E4: N542VL | F4: 46267.017 | G4: 12R | H4: UDGUV2A UDGUV UT78 DURPI DCT NUBIT DCT RIBET UT101 ENAGA DCT OVAGO UT123 IGSON IGSON1B | I4: 340 | J4: I | K4: S | L4: 860 | M4: NUBIT | N4: 46267.063 | O4: 340 | P4: M | Q4: 190 | R4: =IF(G4="12R",_xlfn.XLOOKUP(C4,DB!$A$2:$A$222,DB!$B$2:$B$222,""),IF(G4="30L",_xlfn.XLOOKUP(C4,DB!$A$2:$A$222,DB!$C$2:$C$222,""),"")) -> UDGUV | S4: =HOUR(F4) -> 0 | T4: =_xlfn.XLOOKUP(C4,DB!$A$2:$A$222,DB!$D$2:$D$222,"") -> Sector 2
A5: VOI5589 | B5: MMUN | C5: MMMY | D5: A20N | E5: XATVM | F5: 46267.026 | G5: 12R | H5: S12R T12R6 UN418 UN409 UN419 UN432 NOTEN UT37 SESNO UJ15E RETOS RETOS1A | I5: 380 | J5: I | K5: S | L5: 862 | M5: NOTEN | N5: 46267.07 | O5: 380 | P5: M | Q5: 190 | R5: =IF(G5="12R",_xlfn.XLOOKUP(C5,DB!$A$2:$A$222,DB!$B$2:$B$222,""),IF(G5="30L",_xlfn.XLOOKUP(C5,DB!$A$2:$A$222,DB!$C$2:$C$222,""),"")) -> UDGUV | S5: =HOUR(F5) -> 0 | T5: =_xlfn.XLOOKUP(C5,DB!$A$2:$A$222,DB!$D$2:$D$222,"") -> Sector 2
A6: WFL2502 | B6: MMUN | C6: LEMD | D6: A359 | E6: ECNOI | F6: 46267.035 | G6: 12R | H6: NUDAL1A NUDAL UV106 PODON UG765 MAXIM/N0496F370 Y262 ZFP DCT VENDS DCT NUCAR A699 SUMRS/M085F370 M204 SOORY DCT 42N050W/M085F390 44N040W 46N030W 46N020W/M085F410 DCT PASAS/N0479F410 DCT STG DCT DESAT DCT ZMR | I6: 350 | J6: I | K6: S | L6: 136 | M6: NUDAL | N6: 46267.045 | O6: 218 | P6: H | Q6: 190 | R6: =IF(G6="12R",_xlfn.XLOOKUP(C6,DB!$A$2:$A$222,DB!$B$2:$B$222,""),IF(G6="30L",_xlfn.XLOOKUP(C6,DB!$A$2:$A$222,DB!$C$2:$C$222,""),"")) -> NUDAL | S6: =HOUR(F6) -> 0 | T6: =_xlfn.XLOOKUP(C6,DB!$A$2:$A$222,DB!$D$2:$D$222,"") -> Sector 3
A7: TFL511 | B7: MMUN | C7: EHAM | D7: B788 | E7: PHTFM | F7: 46267.043 | G7: 12R | H7: NUDAL1A NUDAL UV106 PODON UG765 MAXIM DCT EADEN DCT PHK DCT CRANS DCT LENDS DCT ETECK M202 UKOKA/M084F390 M202 MUNEY DCT 41N060W/M084F410 DCT 44N050W DCT 47N040W DCT 50N030W DCT 52N020W DCT MALOT/N0475F410 DCT GISTI DCT LIFFY UL975 WAL M16 DOLAS L603 LAMSO | I7: 390 | J7: I | K7: S | L7: 136 | M7: NUDAL | N7: 46267.052 | O7: 223 | P7: H | Q7: 190 | R7: =IF(G7="12R",_xlfn.XLOOKUP(C7,DB!$A$2:$A$222,DB!$B$2:$B$222,""),IF(G7="30L",_xlfn.XLOOKUP(C7,DB!$A$2:$A$222,DB!$C$2:$C$222,""),"")) -> NUDAL | S7: =HOUR(F7) -> 1 | T7: =_xlfn.XLOOKUP(C7,DB!$A$2:$A$222,DB!$D$2:$D$222,"") -> Sector 3
A8: OBS864 | B8: MMUN | C8: LPPT | D8: A339 | E8: CSTCF | F8: 46267.045 | G8: 12R | H8: S12R T12R6 UN415 UN413 MAXIM/N0476F370 DCT STIFF A699 SUMRS/M082F370 M204 BEXUM/M082F390 DCT ANVER DCT 38N060W DCT 42N050W DCT 44N040W DCT 44N030W DCT 43N020W/M082F410 DCT DETOX/N0465F410 DCT LAZET | I8: 350 | J8: I | K8: S | L8: 137 | M8: 2134N08548W | N8: 46267.054 | O8: 198 | P8: H | Q8: 190 | R8: =IF(G8="12R",_xlfn.XLOOKUP(C8,DB!$A$2:$A$222,DB!$B$2:$B$222,""),IF(G8="30L",_xlfn.XLOOKUP(C8,DB!$A$2:$A$222,DB!$C$2:$C$222,""),"")) -> NUDAL | S8: =HOUR(F8) -> 1 | T8: =_xlfn.XLOOKUP(C8,DB!$A$2:$A$222,DB!$D$2:$D$222,"") -> Sector 3
A9: VIV1373 | B9: MMUN | C9: MMMX | D9: A21N | E9: XAVXD | F9: 46267.047 | G9: 12R | H9: UDGUV2A UDGUV UT78 MEDOS DCT UBVOV DCT UMAVO UT101 ENAGA ENAGA3A | I9: 360 | J9: I | K9: S | L9: 859 | M9: UBVOV | N9: 46267.093 | O9: 360 | P9: M | Q9: 190 | R9: =IF(G9="12R",_xlfn.XLOOKUP(C9,DB!$A$2:$A$222,DB!$B$2:$B$222,""),IF(G9="30L",_xlfn.XLOOKUP(C9,DB!$A$2:$A$222,DB!$C$2:$C$222,""),"")) -> UDGUV | S9: =HOUR(F9) -> 1 | T9: =_xlfn.XLOOKUP(C9,DB!$A$2:$A$222,DB!$D$2:$D$222,"") -> Sector 2
A10: AMX555 | B10: MMUN | C10: MMMX | D10: B39M | E10: XASRB | F10: 46267.05 | G10: 12R | H10: UDGUV2A UDGUV UT78 MEDOS UT20 UBVOV UT101 UMAVO/N0458F300 UT101 ENAGA ENAGA3A | I10: 360 | J10: I | K10: S | L10: 859 | M10: UBVOV | N10: 46267.096 | O10: 360 | P10: M | Q10: 190 | R10: =IF(G10="12R",_xlfn.XLOOKUP(C10,DB!$A$2:$A$222,DB!$B$2:$B$222,""),IF(G10="30L",_xlfn.XLOOKUP(C10,DB!$A$2:$A$222,DB!$C$2:$C$222,""),"")) -> UDGUV | S10: =HOUR(F10) -> 1 | T10: =_xlfn.XLOOKUP(C10,DB!$A$2:$A$222,DB!$D$2:$D$222,"") -> Sector 2
A11: VTM9901 | B11: MMUN | C11: MMQT | D11: B733 | E11: XAVFI | F11: 46267.061 | G11: 12R | H11: S12R 2052N08729W 2147N09330W 2147N09341W 2147N09343W TARBI UJ17 QET | I11: 360 | J11: I | K11: S | L11: 854 | M11: 2145N09459W | N11: 46267.106 | O11: 360 | P11: M | Q11: 190 | R11: =IF(G11="12R",_xlfn.XLOOKUP(C11,DB!$A$2:$A$222,DB!$B$2:$B$222,""),IF(G11="30L",_xlfn.XLOOKUP(C11,DB!$A$2:$A$222,DB!$C$2:$C$222,""),"")) -> UDGUV | S11: =HOUR(F11) -> 1 | T11: =_xlfn.XLOOKUP(C11,DB!$A$2:$A$222,DB!$D$2:$D$222,"") -> Sector 2
A12: AEA064 | B12: MMUN | C12: LEMD | D12: B788 | E12: ECMNS | F12: 46267.077 | G12: 12R | H12: NUDAL1A NUDAL UV106 PODON UG765 MAXIM DCT EYW DCT PBI/M085F370 DCT SNAGY/M084F390 DCT BEXUM M204 LUNKR DCT 38N060W/M084F390 41N050W 43N040W 44N030W 43N020W/M084F410 DCT ARMED/N0478F410 DCT EPOPO/N0483F400 DCT ADORO/N0489F360 L155 ZMR | I12: 370 | J12: I | K12: S | L12: 136 | M12: NUDAL | N12: 46267.087 | O12: 188 | P12: H | Q12: 190 | R12: =IF(G12="12R",_xlfn.XLOOKUP(C12,DB!$A$2:$A$222,DB!$B$2:$B$222,""),IF(G12="30L",_xlfn.XLOOKUP(C12,DB!$A$2:$A$222,DB!$C$2:$C$222,""),"")) -> NUDAL | S12: =HOUR(F12) -> 1 | T12: =_xlfn.XLOOKUP(C12,DB!$A$2:$A$222,DB!$D$2:$D$222,"") -> Sector 3
A13: ESF610 | B13: MMUN | C13: MMMD | D13: B734 | E13: XASLG | F13: 46267.079 | G13: 12R | H13: S12R T12R6 UN418 2052N08723W NAPRI NAPRI1E | I13: 220 | J13: I | K13: S | L13: 324 | M13: MMMD | N13: 46267.101 | O13: 0 | P13: M | Q13: 190 | R13: =IF(G13="12R",_xlfn.XLOOKUP(C13,DB!$A$2:$A$222,DB!$B$2:$B$222,""),IF(G13="30L",_xlfn.XLOOKUP(C13,DB!$A$2:$A$222,DB!$C$2:$C$222,""),"")) -> UDGUV | S13: =HOUR(F13) -> 1 | T13: =_xlfn.XLOOKUP(C13,DB!$A$2:$A$222,DB!$D$2:$D$222,"") -> Sector 2
... A34: AMX511 | B34: MMUN | C34: MMMX | D34: B39M | E34: N469AM | F34: 46267.55 | G34: 12R | H34: UDGUV2A UDGUV UT78 DURPI/N0458F360 UT78 MEDOS UT20 UBVOV UT101 UMAVO/N0456F300 UT101 ENAGA ENAGA3A | I34: 360 | J34: I | K34: S | L34: 859 | M34: UBVOV | N34: 46267.596 | O34: 360 | P34: M | Q34: 190 | R34: =IF(G34="12R",_xlfn.XLOOKUP(C34,DB!$A$2:$A$222,DB!$B$2:$B$222,""),IF(G34="30L",_xlfn.XLOOKUP(C34,DB!$A$2:$A$222,DB!$C$2:$C$222,""),"")) -> UDGUV | S34: =HOUR(F34) -> 13 | T34: =_xlfn.XLOOKUP(C34,DB!$A$2:$A$222,DB!$D$2:$D$222,"") -> Sector 2
A35: XBGPE | B35: MMUN | C35: MMCT | D35: C150 | F35: 46267.577 | G35: 12R | H35: DCT | I35: 25 | J35: V | K35: G | L35: 158 | M35: MMCT | N35: 46267.631 | O35: 1 | P35: L | Q35: 15 | R35: =IF(G35="12R",_xlfn.XLOOKUP(C35,DB!$A$2:$A$222,DB!$B$2:$B$222,""),IF(G35="30L",_xlfn.XLOOKUP(C35,DB!$A$2:$A$222,DB!$C$2:$C$222,""),"")) | S35: =HOUR(F35) -> 13 | T35: =_xlfn.XLOOKUP(C35,DB!$A$2:$A$222,DB!$D$2:$D$222,"")
A36: XAKID | B36: MMUN | C36: KOPF | D36: LJ35 | F36: 46267.579 | G36: 12R | H36: S12R 2101N08650W T12L6 2100N08649W 2101N08647W 2121N08645W 2123N08645W 2132N08642W 2144N08640W 2146N08641W ROTGI LENUK UB646 CANOA DCT EYW DCT | I36: 270 | J36: I | K36: G | L36: 214 | M36: LENUK | N36: 46267.593 | O36: 270 | P36: M | Q36: 40 | R36: =IF(G36="12R",_xlfn.XLOOKUP(C36,DB!$A$2:$A$222,DB!$B$2:$B$222,""),IF(G36="30L",_xlfn.XLOOKUP(C36,DB!$A$2:$A$222,DB!$C$2:$C$222,""),"")) -> OMSUK | S36: =HOUR(F36) -> 13 | T36: =_xlfn.XLOOKUP(C36,DB!$A$2:$A$222,DB!$D$2:$D$222,"") -> Sector 3
A37: UAL1988 | B37: MMUN | C37: KEWR | D37: B39M | E37: N17566 | F37: 46267.581 | G37: 12R | H37: S12R SR00 SR01 SR02 SR03 ROTGI UM219 MYDIA M219 CIGAR/N0462F350 M215 KNOST Q109 CAMJO Q99 QUART PHLBO4 | I37: 330 | J37: I | K37: S | L37: 359 | M37: MYDIA | N37: 46267.601 | O37: 330 | P37: M | Q37: 40 | R37: =IF(G37="12R",_xlfn.XLOOKUP(C37,DB!$A$2:$A$222,DB!$B$2:$B$222,""),IF(G37="30L",_xlfn.XLOOKUP(C37,DB!$A$2:$A$222,DB!$C$2:$C$222,""),"")) -> OMSUK | S37: =HOUR(F37) -> 13 | T37: =_xlfn.XLOOKUP(C37,DB!$A$2:$A$222,DB!$D$2:$D$222,"") -> Sector 3
A38: XAVGF | B38: MMUN | C38: MMUN | D38: B429 | F38: 46267.587 | G38: 12R | H38: 2101N08654W 2053N08706W 2051N08711W 2020N08822W UUCUM | I38: 15 | J38: V | K38: G | L38: 379 | M38: MMUN | N38: 46267.662 | O38: 0 | P38: L | Q38: 15 | R38: =IF(G38="12R",_xlfn.XLOOKUP(C38,DB!$A$2:$A$222,DB!$B$2:$B$222,""),IF(G38="30L",_xlfn.XLOOKUP(C38,DB!$A$2:$A$222,DB!$C$2:$C$222,""),"")) | S38: =HOUR(F38) -> 14 | T38: =_xlfn.XLOOKUP(C38,DB!$A$2:$A$222,DB!$D$2:$D$222,"")
A39: XBMAU | B39: MMUN | C39: MMVR | D39: C501 | F39: 46267.595 | G39: 12R | H39: UDGUV2A UDGUV UJ84 CZA OMPAN DCT | I39: 280 | J39: I | K39: G | L39: 876 | M39: OMPAN | N39: 46267.664 | O39: 231 | P39: L | Q39: 30 | R39: =IF(G39="12R",_xlfn.XLOOKUP(C39,DB!$A$2:$A$222,DB!$B$2:$B$222,""),IF(G39="30L",_xlfn.XLOOKUP(C39,DB!$A$2:$A$222,DB!$C$2:$C$222,""),"")) -> UDGUV | S39: =HOUR(F39) -> 14 | T39: =_xlfn.XLOOKUP(C39,DB!$A$2:$A$222,DB!$D$2:$D$222,"") -> Sector 2
A40: AMX515 | B40: MMUN | C40: MMMX | D40: B39M | E40: XAJSO | F40: 46267.604 | G40: 12R | H40: S12R T12R6 UN418 UBVOV UT101 UMAVO/N0456F300 UT101 ENAGA ENAGA3A | I40: 360 | J40: I | K40: S | L40: 858 | M40: UBVOV | N40: 46267.65 | O40: 360 | P40: M | Q40: 190 | R40: =IF(G40="12R",_xlfn.XLOOKUP(C40,DB!$A$2:$A$222,DB!$B$2:$B$222,""),IF(G40="30L",_xlfn.XLOOKUP(C40,DB!$A$2:$A$222,DB!$C$2:$C$222,""),"")) -> UDGUV | S40: =HOUR(F40) -> 14 | T40: =_xlfn.XLOOKUP(C40,DB!$A$2:$A$222,DB!$D$2:$D$222,"") -> Sector 2
A41: N786BD | B41: MMUN | C41: KFXE | D41: SF50 | F41: 46267.607 | G41: 12R | H41: S12R SR00 SR01 SR02 OMSUK UM219 XOPGI UB646 CANOA DCT EYW DCT | I41: 310 | J41: I | K41: G | L41: 235 | M41: LENUK | N41: 46267.633 | O41: 310 | P41: L | Q41: 40 | R41: =IF(G41="12R",_xlfn.XLOOKUP(C41,DB!$A$2:$A$222,DB!$B$2:$B$222,""),IF(G41="30L",_xlfn.XLOOKUP(C41,DB!$A$2:$A$222,DB!$C$2:$C$222,""),"")) -> NUDAL | S41: =HOUR(F41) -> 14 | T41: =_xlfn.XLOOKUP(C41,DB!$A$2:$A$222,DB!$D$2:$D$222,"") -> Sector 3
A42: VOI5585 | B42: MMUN | C42: MMMY | D42: A20N | E42: XAVSI | F42: 46267.628 | G42: 12R | H42: UDGUV2A UDGUV UT78 DURPI DCT NOTEN UT37 SESNO UJ15E RETOS RETOS1A | I42: 300 | J42: I | K42: S | L42: 878 | M42: NOTEN | N42: 46267.675 | O42: 300 | P42: M | Q42: 190 | R42: =IF(G42="12R",_xlfn.XLOOKUP(C42,DB!$A$2:$A$222,DB!$B$2:$B$222,""),IF(G42="30L",_xlfn.XLOOKUP(C42,DB!$A$2:$A$222,DB!$C$2:$C$222,""),"")) -> UDGUV | S42: =HOUR(F42) -> 15 | T42: =_xlfn.XLOOKUP(C42,DB!$A$2:$A$222,DB!$D$2:$D$222,"") -> Sector 2
A43: JBU1366 | B43: MMUN | C43: KTPA | D43: A320 | E43: N648JB | F43: 46267.632 | G43: 12R | H43: NUDAL1A NUDAL UV106 PODON UG765 MAXIM Y262 LULLS DCT WIGNA/N0448F320 DCT FIPES DCT FERAL BLFRG3 | I43: 330 | J43: I | K43: S | L43: 136 | M43: NUDAL | N43: 46267.642 | O43: 270 | P43: M | Q43: 190 | R43: =IF(G43="12R",_xlfn.XLOOKUP(C43,DB!$A$2:$A$222,DB!$B$2:$B$222,""),IF(G43="30L",_xlfn.XLOOKUP(C43,DB!$A$2:$A$222,DB!$C$2:$C$222,""),"")) -> OMSUK | S43: =HOUR(F43) -> 15 | T43: =_xlfn.XLOOKUP(C43,DB!$A$2:$A$222,DB!$D$2:$D$222,"") -> Sector 3
A44: VIV2278 | B44: MMUN | C44: MMSM | D44: A320 | E44: XAVAJ | F44: 46267.637 | G44: 12R | H44: S12R T12R6 UN418 UN409 UN419 2052N08725W 2051N08728W UBVOV UT20 TAJIN DCT VITOS VITOS2A | I44: 380 | J44: I | K44: S | L44: 859 | M44: UBVOV | N44: 46267.681 | O44: 380 | P44: M | Q44: 190 | R44: =IF(G44="12R",_xlfn.XLOOKUP(C44,DB!$A$2:$A$222,DB!$B$2:$B$222,""),IF(G44="30L",_xlfn.XLOOKUP(C44,DB!$A$2:$A$222,DB!$C$2:$C$222,""),"")) -> UDGUV | S44: =HOUR(F44) -> 15 | T44: =_xlfn.XLOOKUP(C44,DB!$A$2:$A$222,DB!$D$2:$D$222,"") -> Sector 2
A45: VIV7032 | B45: MMUN | C45: MMTO | D45: A320 | E45: XAVAQ | F45: 46267.644 | G45: 12R | H45: S12R T12R6 UN418 UN409 UN419 UN432 UBVOV UT101 UMAVO UT104 LENUL LENUL3A | I45: 380 | J45: I | K45: N | L45: 859 | M45: UBVOV | N45: 46267.688 | O45: 380 | P45: M | Q45: 190 | R45: =IF(G45="12R",_xlfn.XLOOKUP(C45,DB!$A$2:$A$222,DB!$B$2:$B$222,""),IF(G45="30L",_xlfn.XLOOKUP(C45,DB!$A$2:$A$222,DB!$C$2:$C$222,""),"")) -> UDGUV | S45: =HOUR(F45) -> 15 | T45: =_xlfn.XLOOKUP(C45,DB!$A$2:$A$222,DB!$D$2:$D$222,"") -> Sector 2
A46: VIV1029 | B46: MMUN | C46: MMMX | D46: A21N | E46: XAVXV | F46: 46267.648 | G46: 12R | H46: S12R T12R6 UN418 UN409 UN419 UN432 2050N08734W 2049N08739W UBVOV DCT UMAVO UT101 ENAGA ENAGA3A | I46: 360 | J46: I | K46: S | L46: 859 | M46: UBVOV | N46: 46267.693 | O46: 360 | P46: M | Q46: 190 | R46: =IF(G46="12R",_xlfn.XLOOKUP(C46,DB!$A$2:$A$222,DB!$B$2:$B$222,""),IF(G46="30L",_xlfn.XLOOKUP(C46,DB!$A$2:$A$222,DB!$C$2:$C$222,""),"")) -> UDGUV | S46: =HOUR(F46) -> 15 | T46: =_xlfn.XLOOKUP(C46,DB!$A$2:$A$222,DB!$D$2:$D$222,"") -> Sector 2
A47: VIV2164 | B47: MMUN | C47: MMMY | D47: A20N | E47: CCDBF | F47: 46267.653 | G47: 12R | H47: S12R T12R6 UN418 UN409 UN419 2050N08732W 2052N08807W 2054N08851W 2054N08850W 2054N08853W NOTEN UT37 SESNO UJ15E RETOS RETOS1A | I47: 380 | J47: I | K47: S | L47: 875 | M47: NOTEN | N47: 46267.697 | O47: 360 | P47: M | Q47: 190 | R47: =IF(G47="12R",_xlfn.XLOOKUP(C47,DB!$A$2:$A$222,DB!$B$2:$B$222,""),IF(G47="30L",_xlfn.XLOOKUP(C47,DB!$A$2:$A$222,DB!$C$2:$C$222,""),"")) -> UDGUV | S47: =HOUR(F47) -> 15 | T47: =_xlfn.XLOOKUP(C47,DB!$A$2:$A$222,DB!$D$2:$D$222,"") -> Sector 2
A48: AMX591 | B48: MMUN | C48: MMSM | D48: B738 | E48: N377AR | F48: 46267.655 | G48: 12R | H48: S12R T12R6 UN418 UN409 UN419 UN432 UBVOV UT101 UMAVO UT169 VITOS VITOS2A | I48: 360 | J48: I | K48: S | L48: 859 | M48: UBVOV | N48: 46267.7 | O48: 360 | P48: M | Q48: 190 | R48: =IF(G48="12R",_xlfn.XLOOKUP(C48,DB!$A$2:$A$222,DB!$B$2:$B$222,""),IF(G48="30L",_xlfn.XLOOKUP(C48,DB!$A$2:$A$222,DB!$C$2:$C$222,""),"")) -> UDGUV | S48: =HOUR(F48) -> 15 | T48: =_xlfn.XLOOKUP(C48,DB!$A$2:$A$222,DB!$D$2:$D$222,"") -> Sector 2
A49: ESF615 | B49: MMUN | C49: KMIA | D49: B734 | E49: XASLG | F49: 46267.657 | G49: 12R | H49: S12R T12R6 2059N08645W UN102 NUDAL UV106 PODON UG765 EMOVI UG765 MAXIM SNDBR3 | I49: 330 | J49: I | K49: S | L49: 134 | M49: NUDAL | N49: 46267.666 | O49: 264 | P49: M | Q49: 190 | R49: =IF(G49="12R",_xlfn.XLOOKUP(C49,DB!$A$2:$A$222,DB!$B$2:$B$222,""),IF(G49="30L",_xlfn.XLOOKUP(C49,DB!$A$2:$A$222,DB!$C$2:$C$222,""),"")) -> NUDAL | S49: =HOUR(F49) -> 15 | T49: =_xlfn.XLOOKUP(C49,DB!$A$2:$A$222,DB!$D$2:$D$222,"") -> Sector 3
A50: WJA2775 | B50: MMUN | C50: CYYZ | D50: B738 | E50: CFZRM | F50: 46267.659 | G50: 12R | H50: S12R 2059N08647W UN621 2101N08644W UN500 OMSUK ROTGI UM219 MYDIA/M078F370 M219 CIGAR DCT KNOST/N0449F370 DCT CAMJO DCT KERLY DCT FLYYN DCT OXMAN LINNG3 | I50: 370 | J50: I | K50: S | L50: 359 | M50: MYDIA | N50: 46267.68 | O50: 370 | P50: M | Q50: 40 | R50: =IF(G50="12R",_xlfn.XLOOKUP(C50,DB!$A$2:$A$222,DB!$B$2:$B$222,""),IF(G50="30L",_xlfn.XLOOKUP(C50,DB!$A$2:$A$222,DB!$C$2:$C$222,""),"")) -> OMSUK | S50: =HOUR(F50) -> 15 | T50: =_xlfn.XLOOKUP(C50,DB!$A$2:$A$222,DB!$D$2:$D$222,"") -> Sector 3
